Workbook

Sheet Capsule
B1: Basic stock (tồn đầu) | E1: Capsule injection (sản lượng vỏ trứng) | H1: delivery for cotec (xuất cotec) | K1: Niigata capsule packing (Plan) (sản lượng đóng capsule) | N1: Niigata capsule packing (Actua) (sản lượng đóng capsule) | Q1: stock (tồn kho)
A2: 2025 | B2: Yellow | C2: Transparent | D2: Senft | E2: Yellow | F2: Transparent | G2: Senft | H2: Yellow | I2: Transparent | J2: Senft | K2: Yellow | L2: Transparent | M2: Senft | N2: Yellow | O2: Transparent | P2: Senft | Q2: Yellow | R2: Transparent | S2: Senft
A3: Total | E3: =SUM(E4:E69) -> 96133306 | F3: =SUM(F4:F69) -> 1517728 | G3: =SUM(G4:G69) -> 47151193 | H3: =SUM(H4:H69) -> 27900000 | I3: =SUM(I4:I69) -> 0 | J3: =SUM(J4:J69) -> 0 | K3: =SUM(K4:K69) -> 45895200 | L3: =SUM(L4:L69) -> 2870400 | ... P3: =SUM(P4:P69) -> 65294807
A4: 2024/47 | K4: 0 | L4: 0 | M4: 0
A5: 2024/48 | K5: 0 | L5: 0 | M5: 0
A6: 2024/49 | K6: 0 | L6: 0 | M6: 0 | T6: 13
A7: 2024/50 | H7: 9000000 | K7: 0 | L7: 0 | M7: 0
A8: 2024/51 | K8: 0 | L8: 0 | M8: 0 | Q8: =+Q7+E8-H8-N8 -> 0 | R8: =+R7+F8-I8-O8 -> 0 | S8: =+S7+G8-J8-P8 -> 0
A9: 2024/52 | B9: 12408811 | C9: 37400 | D9: 2124306 | K9: 0 | L9: 0 | M9: 936000 | N9: 0 | O9: 0 | Q9: =+B9+E9-H9-N9 -> 12408811 | R9: =+C9+F9-I9-O9 -> 37400 | S9: =+D9+G9-J9-P9 -> 2124306
A10: 2025/01 | E10: 1300462.8 | G10: 262393.34 | H10: 900000 | K10: 0 | L10: 0 | M10: 0 | N10: 412142 | O10: 0 | P10: 458737 | Q10: =+Q9+E10-H10-N10 -> 12397132 | R10: =+R9+F10-I10-O10 -> 37400 | S10: =+S9+G10-J10-P10 -> 1927962.3
A11: 2025/02 | E11: 2115414.5 | G11: 1030690 | K11: 0 | L11: 0 | M11: 1404000 | N11: 1092031 | O11: 0 | P11: 985884 | Q11: =+Q10+E11-H11-N11 -> 13420515 | R11: =+R10+F11-I11-O11 -> 37400 | S11: =+S10+G11-J11-P11 -> 1972768.4
A12: 2025/03 | E12: 1675465.7 | G12: 1559435.1 | K12: 0 | L12: 0 | M12: 936000 | N12: 711539 | O12: 0 | P12: 895588 | Q12: =+Q11+E12-H12-N12 -> 14384442 | R12: =+R11+F12-I12-O12 -> 37400 | S12: =+S11+G12-J12-P12 -> 2636615.5
A13: 2025/04 | E13: 63077.824 | G13: 1031118.3 | H13: 900000 | K13: 0 | L13: 0 | M13: 1404000 | N13: 188627 | O13: 0 | P13: 964536 | Q13: =+Q12+E13-H13-N13 -> 13358893 | R13: =+R12+F13-I13-O13 -> 37400 | S13: =+S12+G13-J13-P13 -> 2703197.8
A14: 2025/05 | E14: 1184442 | K14: 842400 | L14: 0 | M14: 842400 | N14: 0 | O14: 0 | P14: 0 | Q14: =+Q13+E14-H14-N14 -> 14543335 | R14: =+R13+F14-I14-O14 -> 37400 | S14: =+S13+G14-J14-P14 -> 2703197.8
A15: 2025/06 | E15: 1184442 | G15: 508721.05 | K15: 0 | L15: 0 | M15: 0 | N15: 516237 | O15: 0 | P15: 1493352 | Q15: =+Q14+E15-H15-N15 -> 15211540 | R15: =+R14+F15-I15-O15 -> 37400 | S15: =+S14+G15-J15-P15 -> 1718566.8
A16: 2025/07 | E16: 296715.2 | G16: 1398278.5 | H16: 1800000 | K16: 0 | L16: 0 | M16: 936000 | N16: 468000 | O16: 0 | P16: 936000 | Q16: =+Q15+E16-H16-N16 -> 13240255 | R16: =+R15+F16-I16-O16 -> 37400 | S16: =+S15+G16-J16-P16 -> 2180845.3
A17: 2025/08 | E17: 1858065.2 | G17: 1405642.9 | H17: 900000 | K17: 530400 | L17: 0 | M17: 1809600 | N17: 156000 | O17: 0 | P17: 1716000 | Q17: =+Q16+E17-H17-N17 -> 14042320 | R17: =+R16+F17-I17-O17 -> 37400 | S17: =+S16+G17-J17-P17 -> 1870488.2
A18: 2025/09 | E18: 824014.11 | G18: 1645947 | K18: 0 | L18: 0 | M18: 0 | N18: 374400 | O18: 0 | P18: 2340000 | Q18: =+Q17+E18-H18-N18 -> 14491934 | R18: =+R17+F18-I18-O18 -> 37400 | S18: =+S17+G18-J18-P18 -> 1176435.2
A19: 2025/10 | B19: =10971000 -> 10971000 | C19: 37400 | G19: 1643200 | K19: 1029600 | L19: 0 | M19: 4118400 | N19: 1724596 | O19: 0 | P19: 1075626 | Q19: =+Q18+E19-H19-N19 -> 12767338 | R19: =+R18+F19-I19-O19 -> 37400 | S19: =+S18+G19-J19-P19 -> 1744009.2
A20: 2025/11 | D20: 3100000 | E20: 76000 | G20: 1560816 | K20: 624000 | L20: 0 | M20: 2620800 | N20: 2760111 | O20: 0 | P20: 1026122 | Q20: =+Q19+E20-H20-N20 -> 10083227 | R20: =+R19+F20-I20-O20 -> 37400 | S20: =+S19+G20-J20-P20 -> 2278703.2
A21: 2025/12 | G21: =3128480+3128480*0.0006 -> 3130357.1 | H21: 900000 | K21: =+SUM!R34*1000 -> 1684800 | L21: =+SUM!T34*1000 -> 0 | M21: =+SUM!S34*1000 -> 1404000 | N21: 1402115 | O21: =+L21 -> 0 | P21: 1995001 | Q21: =+Q20+E21-H21-N21+3015888 -> 10797000 | R21: =+R20+F21-I21-O21 -> 37400 | S21: =+S20+G21-J21-P21 -> 3414059.2
A22: 2025/13 | G22: 3748920 | K22: =+SUM!R35*1000 -> 1138800 | L22: =+SUM!T35*1000 -> 0 | M22: =+SUM!S35*1000 -> 1045200 | N22: 1476254 | O22: =+L22 -> 0 | P22: 2212812 | Q22: =+Q21+E22-H22-N22 -> 9320746.3 | R22: =+R21+F22-I22-O22 -> 37400 | S22: =+S21+G22-J22-P22 -> 4950167.2
A23: 2025/14 | F23: 902704 | G23: 1792416 | H23: 900000 | K23: =+SUM!R36*1000 -> 1045200 | L23: =+SUM!T36*1000 -> 0 | M23: =+SUM!S36*1000 -> 1279200 | N23: 723821 | O23: =+L23 -> 0 | P23: 1454815 | Q23: =+Q22+E23-H23-N23+900000 -> 8596925.3 | R23: =+R22+F23-I23-O23 -> 940104 | S23: =+S22+G23-J23-P23 -> 5287768.2
A24: 2025/15 | F24: 15024 | G24: 3246058 | K24: =+SUM!R37*1000 -> 982800 | L24: =+SUM!T37*1000 -> 0 | M24: =+SUM!S37*1000 -> 1700400 | N24: 1259070 | O24: =+L24 -> 0 | P24: 1267339 | Q24: =+Q23+E24-H24-N24+300000 -> 7637855.3 | R24: =+R23+F24-I24-O24 -> 955128 | S24: =+S23+G24-J24-P24 -> 7266487.2
A25: 2025/16 | E25: 40800 | G25: 3206400 | H25: 900000 | K25: =+SUM!R38*1000 -> 358800 | L25: =+SUM!T38*1000 -> 0 | M25: =+SUM!S38*1000 -> 1513200 | N25: 1982501 | O25: =+L25 -> 0 | P25: 2082355 | Q25: =+Q24+E25-H25-N25+2800000 -> 7596154.3 | R25: =+R24+F25-I25-O25 -> 955128 | S25: =+S24+G25-J25-P25 -> 8390532.2
A26: 2025/17 | E26: 1494416 | G26: 1369280 | K26: =+SUM!R39*1000 -> 951600 | L26: =+SUM!T39*1000 -> 0 | M26: =+SUM!S39*1000 -> 1201200 | N26: 876620 | O26: =+L26 -> 0 | P26: 2450828 | Q26: =+Q25+E26-H26-N26 -> 8213950.3 | R26: =+R25+F26-I26-O26 -> 955128 | S26: =+S25+G26-J26-P26 -> 7308984.2
A27: 2025/18 | E27: =481591+138400 -> 619991 | G27: =473600+137920 -> 611520 | K27: =+SUM!R40*1000 -> 873600 | L27: =+SUM!T40*1000 -> 0 | M27: =+SUM!S40*1000 -> 2402400 | N27: 501042 | O27: =+L27 -> 0 | P27: 865012 | Q27: =+Q26+E27-H27-N27-328702.3 -> 8004197 | R27: 559611 | S27: =+S26+G27-J27-P27+903544.8 -> 7959037
A28: 2025/19 | G28: 3000000 | K28: =+SUM!R41*1000 -> 2308800 | L28: =+SUM!T41*1000 -> 468000 | M28: =+SUM!S41*1000 -> 2308800 | N28: =+K28 -> 2308800 | O28: =+L28 -> 468000 | P28: =+M28 -> 2308800 | Q28: =+Q27+E28-H28-N28 -> 5695397 | R28: =+R27+F28-I28-O28 -> 91611 | S28: =+S27+G28-J28-P28 -> 8650237
A29: 2025/20 | F29: 600000 | G29: 2400000 | H29: 900000 | K29: =+SUM!R42*1000 -> 717600 | L29: =+SUM!T42*1000 -> 468000 | M29: =+SUM!S42*1000 -> 187200 | N29: =+K29 -> 717600 | O29: =+L29 -> 468000 | P29: =+M29 -> 187200 | Q29: =+Q28+E29-H29-N29 -> 4077797 | R29: =+R28+F29-I29-O29 -> 223611 | S29: =+S28+G29-J29-P29 -> 10863037
A30: 2025/21 | E30: 3000000 | K30: =+SUM!R43*1000 -> 1170000 | L30: =+SUM!T43*1000 -> 468000 | M30: =+SUM!S43*1000 -> 3135600 | N30: =+K30 -> 1170000 | O30: =+L30 -> 468000 | P30: =+M30 -> 3135600 | Q30: =+Q29+E30-H30-N30 -> 5907797 | R30: =+R29+F30-I30-O30 -> -244389 | S30: =+S29+G30-J30-P30 -> 7727437 | T30: =SUM(Q30:S30) -> 13390845
A31: 2025/22 | E31: 3000000 | H31: 900000 | K31: =+SUM!R44*1000 -> 655200 | L31: =+SUM!T44*1000 -> 0 | M31: =+SUM!S44*1000 -> 1497600 | N31: =+K31 -> 655200 | O31: =+L31 -> 0 | P31: =+M31 -> 1497600 | Q31: =+Q30+E31-H31-N31 -> 7352597 | R31: =+R30+F31-I31-O31 -> -244389 | S31: =+S30+G31-J31-P31 -> 6229837 | T31: =SUM(Q31:S31) -> 13338045
A32: 2025/23 | G32: 3000000 | K32: =+SUM!R45*1000 -> 982800 | L32: =+SUM!T45*1000 -> 0 | M32: =+SUM!S45*1000 -> 1076400 | N32: =+K32 -> 982800 | O32: =+L32 -> 0 | P32: =+M32 -> 1076400 | Q32: =+Q31+E32-H32-N32 -> 6369797 | R32: =+R31+F32-I32-O32 -> -244389 | S32: =+S31+G32-J32-P32 -> 8153437 | T32: =SUM(Q32:S32) -> 14278845
A33: 2025/24 | G33: 3000000 | H33: 900000 | K33: =+SUM!R46*1000 -> 702000 | L33: =+SUM!T46*1000 -> 0 | M33: =+SUM!S46*1000 -> 2932800 | N33: =+K33 -> 702000 | O33: =+L33 -> 0 | P33: =+M33 -> 2932800 | Q33: =+Q32+E33-H33-N33 -> 4767797 | R33: =+R32+F33-I33-O33 -> -244389 | S33: =+S32+G33-J33-P33 -> 8220637 | T33: =SUM(Q33:S33) -> 12744045
A34: 2025/25 | E34: 3000000 | H34: 900000 | K34: =+SUM!R47*1000 -> 421200 | L34: =+SUM!T47*1000 -> 0 | M34: =+SUM!S47*1000 -> 1435200 | N34: =+K34 -> 421200 | O34: =+L34 -> 0 | P34: =+M34 -> 1435200 | Q34: =+Q33+E34-H34-N34 -> 6446597 | R34: =+R33+F34-I34-O34 -> -244389 | S34: =+S33+G34-J34-P34 -> 6785437 | T34: =SUM(Q34:S34) -> 12987645
A35: 2025/26 | E35: 3000000 | H35: 900000 | K35: =+SUM!R48*1000 -> 904800 | L35: =+SUM!T48*1000 -> 0 | M35: =+SUM!S48*1000 -> 0 | N35: =+K35 -> 904800 | O35: =+L35 -> 0 | P35: =+M35 -> 0 | Q35: =+Q34+E35-H35-N35 -> 7641797 | R35: =+R34+F35-I35-O35 -> -244389 | S35: =+S34+G35-J35-P35 -> 6785437 | T35: =SUM(Q35:S35) -> 14182845
A36: 2025/27 | E36: 3000000 | K36: =+SUM!R49*1000 -> 249600 | L36: =+SUM!T49*1000 -> 0 | M36: =+SUM!S49*1000 -> 2496000 | N36: =+K36 -> 249600 | O36: =+L36 -> 0 | P36: =+M36 -> 2496000 | Q36: =+Q35+E36-H36-N36 -> 10392197 | R36: =+R35+F36-I36-O36 -> -244389 | S36: =+S35+G36-J36-P36 -> 4289437 | T36: =SUM(Q36:S36) -> 14437245
A37: 2025/28 | G37: 3000000 | H37: 900000 | K37: =+SUM!R50*1000 -> 1404000 | L37: =+SUM!T50*1000 -> 0 | M37: =+SUM!S50*1000 -> 2152800 | N37: =+K37 -> 1404000 | O37: =+L37 -> 0 | P37: =+M37 -> 2152800 | Q37: =+Q36+E37-H37-N37 -> 8088197 | R37: =+R36+F37-I37-O37 -> -244389 | S37: =+S36+G37-J37-P37 -> 5136637 | T37: =SUM(Q37:S37) -> 12980445
A38: 2025/29 | G38: 3000000 | H38: 900000 | K38: =+SUM!R51*1000 -> 187200 | L38: =+SUM!T51*1000 -> 0 | M38: =+SUM!S51*1000 -> 249600 | N38: =+K38 -> 187200 | O38: =+L38 -> 0 | P38: =+M38 -> 249600 | Q38: =+Q37+E38-H38-N38 -> 7000997 | R38: =+R37+F38-I38-O38 -> -244389 | S38: =+S37+G38-J38-P38 -> 7887037 | T38: =SUM(Q38:S38) -> 14643645
A39: 2025/30 | E39: 2400000 | G39: 600000 | H39: 900000 | K39: =+SUM!R52*1000 -> 2667600 | L39: =+SUM!T52*1000 -> 0 | M39: =+SUM!S52*1000 -> 2215200 | N39: =+K39 -> 2667600 | O39: =+L39 -> 0 | P39: =+M39 -> 2215200 | Q39: =+Q38+E39-H39-N39 -> 5833397 | R39: =+R38+F39-I39-O39 -> -244389 | S39: =+S38+G39-J39-P39 -> 6271837 | T39: =SUM(Q39:S39) -> 11860845 | U39: =+T39/550000 -> 21.565173
A40: 2025/31 | E40: 3000000 | H40: 900000 | K40: =+SUM!R53*1000 -> 904800 | L40: =+SUM!T53*1000 -> 0 | M40: =+SUM!S53*1000 -> 1950000 | N40: =+K40 -> 904800 | O40: =+L40 -> 0 | P40: =+M40 -> 1950000 | Q40: =+Q39+E40-H40-N40 -> 7028597 | R40: =+R39+F40-I40-O40 -> -244389 | S40: =+S39+G40-J40-P40 -> 4321837 | T40: =SUM(Q40:S40) -> 11106045 | U40: =+T40/550000 -> 20.192809
...

Sheet Injection
B1: forcast | C1: forcast | D1: 9421 | E1: 9421 | F1: 8822 | G1: 8822 | H1: 8822 | I1: 4026 | J1: 4026 | K1: 11954 | L1: 1321 | M1: 1321 | N1: 1321 | O1: 1321 | P1: 4907 | Q1: 4907 | R1: 4977 | S1: 4977 | T1: 4977 | U1: 4977 | V1: 8349 | W1: 2889 | X1: 2889 | Y1: 2283 | Z1: 2283 | AL1: =SUM(AL5:AL71) -> 23436 | AM1: =SUM(AM5:AM71) -> 26180 | AN1: =SUM(AN5:AN71) -> 1188 | AO1: =SUM(AO5:AO71) -> 1200 | AP1: =SUM(AP5:AP71) -> 102384 | AQ1: =SUM(AQ5:AQ71) -> 91104 | AR1: =SUM(AR5:AR71) -> 6902 | AS1: =SUM(AS5:AS71) -> 11856 | ... BM1: =SUM(BM5:BM71) -> 0 | BP1: =SUM(BP5:BP71) -> 10468.8 | BQ1: =SUM(BQ5:BQ71) -> 10433.6 | BR1: =SUM(BR5:BR71) -> 36736.8 | BS1: =SUM(BS5:BS71) -> 36568.8 | BT1: =SUM(BT5:BT71) -> 36643.2 | BU1: =SUM(BU5:BU71) -> 36475.2
B2: target(K)/W | C2: target(K)/W | D2: 8 | E2: 9 | F2: 5 | G2: 3 | H2: 5 | I2: 7 | J2: 4 | K2: 4 | L2: 6 | M2: 5 | N2: 6 | O2: 4 | P2: 2 | Q2: 2 | R2: 6 | S2: 6 | T2: 6 | U2: 6 | V2: 3 | W2: 7 | X2: 7 | Y2: 3 | Z2: 3 | AA2: 6 | AB2: 6 | AL2: 9 | AM2: 10 | AN2: 5 | AO2: 5 | AP2: 9 | AQ2: 8 | AR2: 7 | AS2: 6 | AT2: 2 | AU2: 2 | AV2: 6 | AW2: 6 | AX2: 6 | AY2: 6 | BP2: Total
B3: Plan | C3: chưa đóng | D3: VS424 | E3: VS429 | F3: VS230 | G3: VS228 | H3: VS233 | I3: VS393 | J3: VS399 | K3: VS010 | L3: VS384 | M3: VS385 | N3: VS384A | O3: VS385A | P3: VS089 | Q3: VS090 | R3: VS193 | S3: VS288 | T3: VS193A | U3: VS288A | V3: VS515 | W3: VC181 | X3: VC182 | Y3: VC248 | Z3: VC249 | AA3: VQ069A | AB3: VQ070A | AL3: VC261 | AM3: VC267 | AN3: VT084 | AO3: VT085 | AP3: VS344 | AQ3: VS369 | AR3: VD387 | AS3: VD424 | AT3: VS089 | AU3: VS090 | AV3: VS193 | AW3: VS288 | AX3: VS193A | AY3: VS288A | BP3: VS089 | BQ3: VS090 | BR3: VS193 | BS3: VS288 | BT3: VS193A | BU3: VS288A
A4: Total | B4: =SUM(B5:B71) -> 920886 | C4: =SUM(C5:C71) -> 290557.2 | D4: =SUM(D5:D71) -> 81993.6 | E4: =SUM(E5:E71) -> 92383.2 | F4: =SUM(F5:F71) -> 43134 | G4: =SUM(G5:G71) -> 25833.6 | H4: =SUM(H5:H71) -> 43056 | I4: =SUM(I5:I71) -> 15834 | ... AB4: =SUM(AB5:AB71) -> 11793.6 | AL4: =SUM(AL5:AL71) -> 23436 | AM4: =SUM(AM5:AM71) -> 26180 | AN4: =SUM(AN5:AN71) -> 1188 | AO4: =SUM(AO5:AO71) -> 1200 | AP4: =SUM(AP5:AP71) -> 102384 | AQ4: =SUM(AQ5:AQ71) -> 91104 | AR4: =SUM(AR5:AR71) -> 6902 | AS4: =SUM(AS5:AS71) -> 11856 | ... DB4: =SUM(DB5:DB71) -> 0
A5: 2025/42 | B5: =SUM(D5:BJ5) -> 5240 | D5: =+Production!D5*Injection!$D$2 -> 0 | E5: =+Production!E5*Injection!$E$2 -> 0 | F5: =+Production!F5*Injection!$F$2 -> 0 | G5: =+Production!G5*Injection!$G$2 -> 0 | H5: =+Production!H5*Injection!$H$2 -> 0 | I5: =+Production!I5*Injection!$I$2 -> 0 | J5: =+Production!J5*Injection!$J$2 -> 0 | K5: =+Production!K5*Injection!$K$2 -> 0 | L5: =+Production!L5*Injection!$L$2 -> 0 | M5: =+Production!M5*Injection!$M$2 -> 0 | N5: =+Production!N5*Injection!$N$2 -> 0 | O5: =+Production!O5*Injection!$O$2 -> 0 | P5: =+Production!P5*Injection!$P$2 -> 0 | Q5: =+Production!Q5*Injection!$Q$2 -> 0 | R5: =+Production!R5*Injection!$R$2 -> 0 | S5: =+Production!S5*$S$2 -> 0 | T5: =+Production!T5*$T$2 -> 0 | U5: =+Production!U5*$U$2 -> 0 | V5: =+Production!V5*$V$2 -> 0 | W5: =+Production!W5*$W$2 -> 0 | X5: =+Production!X5*$X$2 -> 0 | Y5: =+Production!Y5*$Y$2 -> 0 | Z5: =+Production!Z5*$Z$2 -> 0 | AA5: =+Production!AA5*$AA$2 -> 0 | AB5: =+Production!AB5*$AB$2 -> 0 | AL5: =+Production!AO5*Injection!$AL$2 -> 2520 | AM5: =+Production!AP5*Injection!$AM$2 -> 2720 | AN5: =+Production!AQ5*$AN$2 -> 0 | AO5: =+Production!AR5*$AO$2 -> 0 | AP5: =+Production!AS5*$AP$2 -> 0 | AQ5: =+Production!AT5*$AQ$2 -> 0 | AR5: =+Production!AU5*$AR$2 -> 0 | AS5: =+Production!AV5*$AS$2 -> 0 | AT5: =+Production!AW5*$AT$2 -> 0 | AU5: =+Production!AX5*$AU$2 -> 0 | AV5: =+Production!AY5*$AV$2 -> 0 | AW5: =+Production!AZ5*$AW$2 -> 0 | AX5: =+Production!BA5*$AX$2 -> 0 | AY5: =+Production!BB5*$AY$2 -> 0 | BP5: =+P5+AT5 -> 0 | BQ5: =+Q5+AU5 -> 0 | BR5: =R5+AV5 -> 0 | BS5: =S5+AW5 -> 0 | BT5: =T5+AX5 -> 0 | BU5: =U5+AY5 -> 0
A6: 2025/43 | B6: =SUM(D6:BJ6) -> 6084 | D6: =+Production!D6*Injection!$D$2 -> 0 | E6: =+Production!E6*Injection!$E$2 -> 0 | F6: =+Production!F6*Injection!$F$2 -> 0 | G6: =+Production!G6*Injection!$G$2 -> 0 | H6: =+Production!H6*Injection!$H$2 -> 0 | I6: =+Production!I6*Injection!$I$2 -> 0 | J6: =+Production!J6*Injection!$J$2 -> 0 | K6: =+Production!K6*Injection!$K$2 -> 0 | L6: =+Production!L6*Injection!$L$2 -> 0 | M6: =+Production!M6*Injection!$M$2 -> 0 | N6: =+Production!N6*Injection!$N$2 -> 0 | O6: =+Production!O6*Injection!$O$2 -> 0 | P6: =+Production!P6*Injection!$P$2 -> 0 | Q6: =+Production!Q6*Injection!$Q$2 -> 0 | R6: =+Production!R6*Injection!$R$2 -> 0 | S6: =+Production!S6*Injection!$S$2 -> 0 | T6: =+Production!T6*$T$2 -> 0 | U6: =+Production!U6*$U$2 -> 0 | V6: =+Production!V6*$V$2 -> 0 | W6: =+Production!W6*$W$2 -> 0 | X6: =+Production!X6*$X$2 -> 0 | Y6: =+Production!Y6*$Y$2 -> 0 | Z6: =+Production!Z6*$Z$2 -> 0 | AA6: =+Production!AA6*$AA$2 -> 0 | AB6: =+Production!AB6*$AB$2 -> 0 | AL6: =+Production!AO6*Injection!$AL$2 -> 3024 | AM6: =+Production!AP6*Injection!$AM$2 -> 3060 | AN6: =+Production!AQ6*$AN$2 -> 0 | AO6: =+Production!AR6*$AO$2 -> 0 | AP6: =+Production!AS6*$AP$2 -> 0 | AQ6: =+Production!AT6*$AQ$2 -> 0 | AR6: =+Production!AU6*$AR$2 -> 0 | AS6: =+Production!AV6*$AS$2 -> 0 | AT6: =+Production!AW6*$AT$2 -> 0 | AU6: =+Production!AX6*$AU$2 -> 0 | AV6: =+Production!AY6*$AV$2 -> 0 | AW6: =+Production!AZ6*$AW$2 -> 0 | AX6: =+Production!BA6*$AX$2 -> 0 | AY6: =+Production!BB6*$AY$2 -> 0 | BP6: =+P6+AT6 -> 0 | BQ6: =+Q6+AU6 -> 0 | BR6: =R6+AV6 -> 0 | BS6: =S6+AW6 -> 0 | BT6: =T6+AX6 -> 0 | BU6: =U6+AY6 -> 0
A7: 2025/44 | B7: =SUM(D7:BJ7) -> 0 | D7: =+Production!D7*Injection!$D$2 -> 0 | E7: =+Production!E7*Injection!$E$2 -> 0 | F7: =+Production!F7*Injection!$F$2 -> 0 | G7: =+Production!G7*Injection!$G$2 -> 0 | H7: =+Production!H7*Injection!$H$2 -> 0 | I7: =+Production!I7*Injection!$I$2 -> 0 | J7: =+Production!J7*Injection!$J$2 -> 0 | K7: =+Production!K7*Injection!$K$2 -> 0 | L7: =+Production!L7*Injection!$L$2 -> 0 | M7: =+Production!M7*Injection!$M$2 -> 0 | N7: =+Production!N7*Injection!$N$2 -> 0 | O7: =+Production!O7*Injection!$O$2 -> 0 | P7: =+Production!P7*Injection!$P$2 -> 0 | Q7: =+Production!Q7*Injection!$Q$2 -> 0 | R7: =+Production!R7*Injection!$R$2 -> 0 | S7: =+Production!S7*Injection!$S$2 -> 0 | T7: =+Production!T7*$T$2 -> 0 | U7: =+Production!U7*$U$2 -> 0 | V7: =+Production!V7*$V$2 -> 0 | W7: =+Production!W7*$W$2 -> 0 | X7: =+Production!X7*$X$2 -> 0 | Y7: =+Production!Y7*$Y$2 -> 0 | Z7: =+Production!Z7*$Z$2 -> 0 | AA7: =+Production!AA7*$AA$2 -> 0 | AB7: =+Production!AB7*$AB$2 -> 0 | AL7: =+Production!AO7*Injection!$AL$2 -> 0 | AM7: =+Production!AP7*Injection!$AM$2 -> 0 | AN7: =+Production!AQ7*$AN$2 -> 0 | AO7: =+Production!AR7*$AO$2 -> 0 | AP7: =+Production!AS7*$AP$2 -> 0 | AQ7: =+Production!AT7*$AQ$2 -> 0 | AR7: =+Production!AU7*$AR$2 -> 0 | AS7: =+Production!AV7*$AS$2 -> 0 | AT7: =+Production!AW7*$AT$2 -> 0 | AU7: =+Production!AX7*$AU$2 -> 0 | AV7: =+Production!AY7*$AV$2 -> 0 | AW7: =+Production!AZ7*$AW$2 -> 0 | AX7: =+Production!BA7*$AX$2 -> 0 | AY7: =+Production!BB7*$AY$2 -> 0 | BP7: =+P7+AT7 -> 0 | BQ7: =+Q7+AU7 -> 0 | BR7: =R7+AV7 -> 0 | BS7: =S7+AW7 -> 0 | BT7: =T7+AX7 -> 0 | BU7: =U7+AY7 -> 0
A8: 2025/45 | B8: =SUM(D8:BJ8) -> 4736 | D8: =+Production!D8*Injection!$D$2 -> 0 | E8: =+Production!E8*Injection!$E$2 -> 0 | F8: =+Production!F8*Injection!$F$2 -> 0 | G8: =+Production!G8*Injection!$G$2 -> 0 | H8: =+Production!H8*Injection!$H$2 -> 0 | I8: =+Production!I8*Injection!$I$2 -> 0 | J8: =+Production!J8*Injection!$J$2 -> 0 | K8: =+Production!K8*Injection!$K$2 -> 0 | L8: =+Production!L8*Injection!$L$2 -> 0 | M8: =+Production!M8*Injection!$M$2 -> 0 | N8: =+Production!N8*Injection!$N$2 -> 0 | O8: =+Production!O8*Injection!$O$2 -> 0 | P8: =+Production!P8*Injection!$P$2 -> 0 | Q8: =+Production!Q8*Injection!$Q$2 -> 0 | R8: =+Production!R8*Injection!$R$2 -> 0 | S8: =+Production!S8*Injection!$S$2 -> 0 | T8: =+Production!T8*$T$2 -> 0 | U8: =+Production!U8*$U$2 -> 0 | V8: =+Production!V8*$V$2 -> 0 | W8: =+Production!W8*$W$2 -> 0 | X8: =+Production!X8*$X$2 -> 0 | Y8: =+Production!Y8*$Y$2 -> 0 | Z8: =+Production!Z8*$Z$2 -> 0 | AA8: =+Production!AA8*$AA$2 -> 0 | AB8: =+Production!AB8*$AB$2 -> 0 | AL8: =+Production!AO8*Injection!$AL$2 -> 2016 | AM8: =+Production!AP8*Injection!$AM$2 -> 2720 | AN8: =+Production!AQ8*$AN$2 -> 0 | AO8: =+Production!AR8*$AO$2 -> 0 | AP8: =+Production!AS8*$AP$2 -> 0 | AQ8: =+Production!AT8*$AQ$2 -> 0 | AR8: =+Production!AU8*$AR$2 -> 0 | AS8: =+Production!AV8*$AS$2 -> 0 | AT8: =+Production!AW8*$AT$2 -> 0 | AU8: =+Production!AX8*$AU$2 -> 0 | AV8: =+Production!AY8*$AV$2 -> 0 | AW8: =+Production!AZ8*$AW$2 -> 0 | AX8: =+Production!BA8*$AX$2 -> 0 | AY8: =+Production!BB8*$AY$2 -> 0 | BP8: =+P8+AT8 -> 0 | BQ8: =+Q8+AU8 -> 0 | BR8: =R8+AV8 -> 0 | BS8: =S8+AW8 -> 0 | BT8: =T8+AX8 -> 0 | BU8: =U8+AY8 -> 0
A9: 2025/46 | B9: =SUM(D9:BJ9) -> 13440 | D9: =+Production!D9*Injection!$D$2 -> 0 | E9: =+Production!E9*Injection!$E$2 -> 0 | F9: =+Production!F9*Injection!$F$2 -> 0 | G9: =+Production!G9*Injection!$G$2 -> 0 | H9: =+Production!H9*Injection!$H$2 -> 0 | I9: =+Production!I9*Injection!$I$2 -> 0 | J9: =+Production!J9*Injection!$J$2 -> 0 | K9: =+Production!K9*Injection!$K$2 -> 0 | L9: =+Production!L9*Injection!$L$2 -> 0 | M9: =+Production!M9*Injection!$M$2 -> 0 | N9: =+Production!N9*Injection!$N$2 -> 0 | O9: =+Production!O9*Injection!$O$2 -> 0 | P9: =+Production!P9*Injection!$P$2 -> 0 | Q9: =+Production!Q9*Injection!$Q$2 -> 0 | R9: =+Production!R9*Injection!$R$2 -> 0 | S9: =+Production!S9*Injection!$S$2 -> 0 | T9: =+Production!T9*$T$2 -> 0 | U9: =+Production!U9*$U$2 -> 0 | V9: =+Production!V9*$V$2 -> 0 | W9: =+Production!W9*$W$2 -> 0 | X9: =+Production!X9*$X$2 -> 0 | Y9: =+Production!Y9*$Y$2 -> 0 | Z9: =+Production!Z9*$Z$2 -> 0 | AA9: =+Production!AA9*$AA$2 -> 0 | AB9: =+Production!AB9*$AB$2 -> 0 | AL9: =+Production!AO9*Injection!$AL$2 -> 6300 | AM9: =+Production!AP9*Injection!$AM$2 -> 7140 | AN9: =+Production!AQ9*$AN$2 -> 0 | AO9: =+Production!AR9*$AO$2 -> 0 | AP9: =+Production!AS9*$AP$2 -> 0 | AQ9: =+Production!AT9*$AQ$2 -> 0 | AR9: =+Production!AU9*$AR$2 -> 0 | AS9: =+Production!AV9*$AS$2 -> 0 | AT9: =+Production!AW9*$AT$2 -> 0 | AU9: =+Production!AX9*$AU$2 -> 0 | AV9: =+Production!AY9*$AV$2 -> 0 | AW9: =+Production!AZ9*$AW$2 -> 0 | AX9: =+Production!BA9*$AX$2 -> 0 | AY9: =+Production!BB9*$AY$2 -> 0 | BP9: =+P9+AT9 -> 0 | BQ9: =+Q9+AU9 -> 0 | BR9: =R9+AV9 -> 0 | BS9: =S9+AW9 -> 0 | BT9: =T9+AX9 -> 0 | BU9: =U9+AY9 -> 0 | CK9: =+BA9 -> 0 | CL9: =+BB9 -> 0
A10: 2025/47 | B10: =SUM(D10:BJ10) -> 4648 | D10: =+Production!D10*Injection!$D$2 -> 0 | E10: =+Production!E10*Injection!$E$2 -> 0 | F10: =+Production!F10*Injection!$F$2 -> 0 | G10: =+Production!G10*Injection!$G$2 -> 0 | H10: =+Production!H10*Injection!$H$2 -> 0 | I10: =+Production!I10*Injection!$I$2 -> 0 | J10: =+Production!J10*Injection!$J$2 -> 0 | K10: =+Production!K10*Injection!$K$2 -> 0 | L10: =+Production!L10*Injection!$L$2 -> 0 | M10: =+Production!M10*Injection!$M$2 -> 0 | N10: =+Production!N10*Injection!$N$2 -> 0 | O10: =+Production!O10*Injection!$O$2 -> 0 | P10: =+Production!P10*Injection!$P$2 -> 0 | Q10: =+Production!Q10*Injection!$Q$2 -> 0 | R10: =+Production!R10*Injection!$R$2 -> 0 | S10: =+Production!S10*Injection!$S$2 -> 0 | T10: =+Production!T10*$T$2 -> 0 | U10: =+Production!U10*$U$2 -> 0 | V10: =+Production!V10*$V$2 -> 0 | W10: =+Production!W10*$W$2 -> 0 | X10: =+Production!X10*$X$2 -> 0 | Y10: =+Production!Y10*$Y$2 -> 0 | Z10: =+Production!Z10*$Z$2 -> 0 | AA10: =+Production!AA10*$AA$2 -> 0 | AB10: =+Production!AB10*$AB$2 -> 0 | AL10: =+Production!AO10*Injection!$AL$2 -> 2268 | AM10: =+Production!AP10*Injection!$AM$2 -> 2380 | AN10: =+Production!AQ10*$AN$2 -> 0 | AO10: =+Production!AR10*$AO$2 -> 0 | AP10: =+Production!AS10*$AP$2 -> 0 | AQ10: =+Production!AT10*$AQ$2 -> 0 | AR10: =+Production!AU10*$AR$2 -> 0 | AS10: =+Production!AV10*$AS$2 -> 0 | AT10: =+Production!AW10*$AT$2 -> 0 | AU10: =+Production!AX10*$AU$2 -> 0 | AV10: =+Production!AY10*$AV$2 -> 0 | AW10: =+Production!AZ10*$AW$2 -> 0 | AX10: =+Production!BA10*$AX$2 -> 0 | AY10: =+Production!BB10*$AY$2 -> 0 | BP10: =+P10+AT10 -> 0 | BQ10: =+Q10+AU10 -> 0 | BR10: =R10+AV10 -> 0 | BS10: =S10+AW10 -> 0 | BT10: =T10+AX10 -> 0 | BU10: =U10+AY10 -> 0 | CK10: =+BA10 -> 0 | CL10: =+BB10 -> 0
A11: 2025/48 | B11: =SUM(D11:BJ11) -> 0 | D11: =+Production!D11*Injection!$D$2 -> 0 | E11: =+Production!E11*Injection!$E$2 -> 0 | F11: =+Production!F11*Injection!$F$2 -> 0 | G11: =+Production!G11*Injection!$G$2 -> 0 | H11: =+Production!H11*Injection!$H$2 -> 0 | I11: =+Production!I11*Injection!$I$2 -> 0 | J11: =+Production!J11*Injection!$J$2 -> 0 | K11: =+Production!K11*Injection!$K$2 -> 0 | L11: =+Production!L11*Injection!$L$2 -> 0 | M11: =+Production!M11*Injection!$M$2 -> 0 | N11: =+Production!N11*Injection!$N$2 -> 0 | O11: =+Production!O11*Injection!$O$2 -> 0 | P11: =+Production!P11*Injection!$P$2 -> 0 | Q11: =+Production!Q11*Injection!$Q$2 -> 0 | R11: =+Production!R11*Injection!$R$2 -> 0 | S11: =+Production!S11*Injection!$S$2 -> 0 | T11: =+Production!T11*$T$2 -> 0 | U11: =+Production!U11*$U$2 -> 0 | V11: =+Production!V11*$V$2 -> 0 | W11: =+Production!W11*$W$2 -> 0 | X11: =+Production!X11*$X$2 -> 0 | Y11: =+Production!Y11*$Y$2 -> 0 | Z11: =+Production!Z11*$Z$2 -> 0 | AA11: =+Production!AA11*$AA$2 -> 0 | AB11: =+Production!AB11*$AB$2 -> 0 | AL11: =+Production!AO11*Injection!$AL$2 -> 0 | AM11: =+Production!AP11*Injection!$AM$2 -> 0 | AN11: =+Production!AQ11*$AN$2 -> 0 | AO11: =+Production!AR11*$AO$2 -> 0 | AP11: =+Production!AS11*$AP$2 -> 0 | AQ11: =+Production!AT11*$AQ$2 -> 0 | AR11: =+Production!AU11*$AR$2 -> 0 | AS11: =+Production!AV11*$AS$2 -> 0 | AT11: =+Production!AW11*$AT$2 -> 0 | AU11: =+Production!AX11*$AU$2 -> 0 | AV11: =+Production!AY11*$AV$2 -> 0 | AW11: =+Production!AZ11*$AW$2 -> 0 | AX11: =+Production!BA11*$AX$2 -> 0 | AY11: =+Production!BB11*$AY$2 -> 0 | BP11: =+P11+AT11 -> 0 | BQ11: =+Q11+AU11 -> 0 | BR11: =R11+AV11 -> 0 | BS11: =S11+AW11 -> 0 | BT11: =T11+AX11 -> 0 | BU11: =U11+AY11 -> 0 | CK11: =+BA11 -> 0 | CL11: =+BB11 -> 0
A12: 2025/49 | B12: =SUM(D12:BJ12) -> 0 | D12: =+Production!D12*Injection!$D$2 -> 0 | E12: =+Production!E12*Injection!$E$2 -> 0 | F12: =+Production!F12*Injection!$F$2 -> 0 | G12: =+Production!G12*Injection!$G$2 -> 0 | H12: =+Production!H12*Injection!$H$2 -> 0 | I12: =+Production!I12*Injection!$I$2 -> 0 | J12: =+Production!J12*Injection!$J$2 -> 0 | K12: =+Production!K12*Injection!$K$2 -> 0 | L12: =+Production!L12*Injection!$L$2 -> 0 | M12: =+Production!M12*Injection!$M$2 -> 0 | N12: =+Production!N12*Injection!$N$2 -> 0 | O12: =+Production!O12*Injection!$O$2 -> 0 | P12: =+Production!P12*Injection!$P$2 -> 0 | Q12: =+Production!Q12*Injection!$Q$2 -> 0 | R12: =+Production!R12*Injection!$R$2 -> 0 | S12: =+Production!S12*Injection!$S$2 -> 0 | T12: =+Production!T12*$T$2 -> 0 | U12: =+Production!U12*$U$2 -> 0 | V12: =+Production!V12*$V$2 -> 0 | W12: =+Production!W12*$W$2 -> 0 | X12: =+Production!X12*$X$2 -> 0 | Y12: =+Production!Y12*$Y$2 -> 0 | Z12: =+Production!Z12*$Z$2 -> 0 | AA12: =+Production!AA12*$AA$2 -> 0 | AB12: =+Production!AB12*$AB$2 -> 0 | AL12: =+Production!AO12*Injection!$AL$2 -> 0 | AM12: =+Production!AP12*Injection!$AM$2 -> 0 | AN12: =+Production!AQ12*$AN$2 -> 0 | AO12: =+Production!AR12*$AO$2 -> 0 | AP12: =+Production!AS12*$AP$2 -> 0 | AQ12: =+Production!AT12*$AQ$2 -> 0 | AR12: =+Production!AU12*$AR$2 -> 0 | AS12: =+Production!AV12*$AS$2 -> 0 | AT12: =+Production!AW12*$AT$2 -> 0 | AU12: =+Production!AX12*$AU$2 -> 0 | AV12: =+Production!AY12*$AV$2 -> 0 | AW12: =+Production!AZ12*$AW$2 -> 0 | AX12: =+Production!BA12*$AX$2 -> 0 | AY12: =+Production!BB12*$AY$2 -> 0 | BP12: =+P12+AT12 -> 0 | BQ12: =+Q12+AU12 -> 0 | BR12: =R12+AV12 -> 0 | BS12: =S12+AW12 -> 0 | BT12: =T12+AX12 -> 0 | BU12: =U12+AY12 -> 0 | CK12: =+BA12 -> 0 | CL12: =+BB12 -> 0
A13: 2025/50 | B13: =SUM(D13:BJ13) -> 4056 | D13: =+Production!D13*Injection!$D$2 -> 0 | E13: =+Production!E13*Injection!$E$2 -> 0 | F13: =+Production!F13*Injection!$F$2 -> 1560 | G13: =+Production!G13*Injection!$G$2 -> 936 | H13: =+Production!H13*Injection!$H$2 -> 1560 | I13: =+Production!I13*Injection!$I$2 -> 0 | J13: =+Production!J13*Injection!$J$2 -> 0 | K13: =+Production!K13*Injection!$K$2 -> 0 | L13: =+Production!L13*Injection!$L$2 -> 0 | M13: =+Production!M13*Injection!$M$2 -> 0 | N13: =+Production!N13*Injection!$N$2 -> 0 | O13: =+Production!O13*Injection!$O$2 -> 0 | P13: =+Production!P13*Injection!$P$2 -> 0 | Q13: =+Production!Q13*Injection!$Q$2 -> 0 | R13: =+Production!R13*Injection!$R$2 -> 0 | S13: =+Production!S13*Injection!$S$2 -> 0 | T13: =+Production!T13*$T$2 -> 0 | U13: =+Production!U13*$U$2 -> 0 | V13: =+Production!V13*$V$2 -> 0 | W13: =+Production!W13*$W$2 -> 0 | X13: =+Production!X13*$X$2 -> 0 | Y13: =+Production!Y13*$Y$2 -> 0 | Z13: =+Production!Z13*$Z$2 -> 0 | AA13: =+Production!AA13*$AA$2 -> 0 | AB13: =+Production!AB13*$AB$2 -> 0 | AL13: =+Production!AO13*Injection!$AL$2 -> 0 | AM13: =+Production!AP13*Injection!$AM$2 -> 0 | AN13: =+Production!AQ13*$AN$2 -> 0 | AO13: =+Production!AR13*$AO$2 -> 0 | AP13: =+Production!AS13*$AP$2 -> 0 | AQ13: =+Production!AT13*$AQ$2 -> 0 | AR13: =+Production!AU13*$AR$2 -> 0 | AS13: =+Production!AV13*$AS$2 -> 0 | AT13: =+Production!AW13*$AT$2 -> 0 | AU13: =+Production!AX13*$AU$2 -> 0 | AV13: =+Production!AY13*$AV$2 -> 0 | AW13: =+Production!AZ13*$AW$2 -> 0 | AX13: =+Production!BA13*$AX$2 -> 0 | AY13: =+Production!BB13*$AY$2 -> 0 | BP13: =+P13+AT13 -> 0 | BQ13: =+Q13+AU13 -> 0 | BR13: =R13+AV13 -> 0 | BS13: =S13+AW13 -> 0 | BT13: =T13+AX13 -> 0 | BU13: =U13+AY13 -> 0 | CK13: =+BA13 -> 0 | CL13: =+BB13 -> 0
A14: 2025/51 | B14: =SUM(D14:BJ14) -> 0 | D14: =+Production!D14*Injection!$D$2 -> 0 | E14: =+Production!E14*Injection!$E$2 -> 0 | F14: =+Production!F14*Injection!$F$2 -> 0 | G14: =+Production!G14*Injection!$G$2 -> 0 | H14: =+Production!H14*Injection!$H$2 -> 0 | I14: =+Production!I14*Injection!$I$2 -> 0 | J14: =+Production!J14*Injection!$J$2 -> 0 | K14: =+Production!K14*Injection!$K$2 -> 0 | L14: =+Production!L14*Injection!$L$2 -> 0 | M14: =+Production!M14*Injection!$M$2 -> 0 | N14: =+Production!N14*Injection!$N$2 -> 0 | O14: =+Production!O14*Injection!$O$2 -> 0 | P14: =+Production!P14*Injection!$P$2 -> 0 | Q14: =+Production!Q14*Injection!$Q$2 -> 0 | R14: =+Production!R14*Injection!$R$2 -> 0 | S14: =+Production!S14*Injection!$S$2 -> 0 | T14: =+Production!T14*$T$2 -> 0 | U14: =+Production!U14*$U$2 -> 0 | V14: =+Production!V14*$V$2 -> 0 | W14: =+Production!W14*$W$2 -> 0 | X14: =+Production!X14*$X$2 -> 0 | Y14: =+Production!Y14*$Y$2 -> 0 | Z14: =+Production!Z14*$Z$2 -> 0 | AA14: =+Production!AA14*$AA$2 -> 0 | AB14: =+Production!AB14*$AB$2 -> 0 | AL14: =+Production!AO14*Injection!$AL$2 -> 0 | AM14: =+Production!AP14*Injection!$AM$2 -> 0 | AN14: =+Production!AQ14*$AN$2 -> 0 | AO14: =+Production!AR14*$AO$2 -> 0 | AP14: =+Production!AS14*$AP$2 -> 0 | AQ14: =+Production!AT14*$AQ$2 -> 0 | AR14: =+Production!AU14*$AR$2 -> 0 | AS14: =+Production!AV14*$AS$2 -> 0 | AT14: =+Production!AW14*$AT$2 -> 0 | AU14: =+Production!AX14*$AU$2 -> 0 | AV14: =+Production!AY14*$AV$2 -> 0 | AW14: =+Production!AZ14*$AW$2 -> 0 | AX14: =+Production!BA14*$AX$2 -> 0 | AY14: =+Production!BB14*$AY$2 -> 0 | BP14: =+P14+AT14 -> 0 | BQ14: =+Q14+AU14 -> 0 | BR14: =R14+AV14 -> 0 | BS14: =S14+AW14 -> 0 | BT14: =T14+AX14 -> 0 | BU14: =U14+AY14 -> 0 | CK14: =+BA14 -> 0 | CL14: =+BB14 -> 0
A15: 2025/52 | B15: =SUM(D15:BJ15) -> 4056 | D15: =+Production!D15*Injection!$D$2 -> 0 | E15: =+Production!E15*Injection!$E$2 -> 0 | F15: =+Production!F15*Injection!$F$2 -> 1560 | G15: =+Production!G15*Injection!$G$2 -> 936 | H15: =+Production!H15*Injection!$H$2 -> 1560 | I15: =+Production!I15*Injection!$I$2 -> 0 | J15: =+Production!J15*Injection!$J$2 -> 0 | K15: =+Production!K15*Injection!$K$2 -> 0 | L15: =+Production!L15*Injection!$L$2 -> 0 | M15: =+Production!M15*Injection!$M$2 -> 0 | N15: =+Production!N15*Injection!$N$2 -> 0 | O15: =+Production!O15*Injection!$O$2 -> 0 | P15: =+Production!P15*Injection!$P$2 -> 0 | Q15: =+Production!Q15*Injection!$Q$2 -> 0 | R15: =+Production!R15*Injection!$R$2 -> 0 | S15: =+Production!S15*Injection!$S$2 -> 0 | T15: =+Production!T15*$T$2 -> 0 | U15: =+Production!U15*$U$2 -> 0 | V15: =+Production!V15*$V$2 -> 0 | W15: =+Production!W15*$W$2 -> 0 | X15: =+Production!X15*$X$2 -> 0 | Y15: =+Production!Y15*$Y$2 -> 0 | Z15: =+Production!Z15*$Z$2 -> 0 | AA15: =+Production!AA15*$AA$2 -> 0 | AB15: =+Production!AB15*$AB$2 -> 0 | AL15: =+Production!AO15*Injection!$AL$2 -> 0 | AM15: =+Production!AP15*Injection!$AM$2 -> 0 | AN15: =+Production!AQ15*$AN$2 -> 0 | AO15: =+Production!AR15*$AO$2 -> 0 | AP15: =+Production!AS15*$AP$2 -> 0 | AQ15: =+Production!AT15*$AQ$2 -> 0 | AR15: =+Production!AU15*$AR$2 -> 0 | AS15: =+Production!AV15*$AS$2 -> 0 | AT15: =+Production!AW15*$AT$2 -> 0 | AU15: =+Production!AX15*$AU$2 -> 0 | AV15: =+Production!AY15*$AV$2 -> 0 | AW15: =+Production!AZ15*$AW$2 -> 0 | AX15: =+Production!BA15*$AX$2 -> 0 | AY15: =+Production!BB15*$AY$2 -> 0 | BP15: =+P15+AT15 -> 0 | BQ15: =+Q15+AU15 -> 0 | BR15: =R15+AV15 -> 0 | BS15: =S15+AW15 -> 0 | BT15: =T15+AX15 -> 0 | BU15: =U15+AY15 -> 0 | CK15: =+BA15 -> 0 | CL15: =+BB15 -> 0
A16: 2026/01 | B16: =SUM(D16:BJ16) -> 2388 | D16: =+Production!D16*Injection!$D$2 -> 0 | E16: =+Production!E16*Injection!$E$2 -> 0 | F16: =+Production!F16*Injection!$F$2 -> 0 | G16: =+Production!G16*Injection!$G$2 -> 0 | H16: =+Production!H16*Injection!$H$2 -> 0 | I16: =+Production!I16*Injection!$I$2 -> 0 | J16: =+Production!J16*Injection!$J$2 -> 0 | K16: =+Production!K16*Injection!$K$2 -> 0 | L16: =+Production!L16*Injection!$L$2 -> 0 | M16: =+Production!M16*Injection!$M$2 -> 0 | N16: =+Production!N16*Injection!$N$2 -> 0 | O16: =+Production!O16*Injection!$O$2 -> 0 | P16: =+Production!P16*Injection!$P$2 -> 0 | Q16: =+Production!Q16*Injection!$Q$2 -> 0 | R16: =+Production!R16*Injection!$R$2 -> 0 | S16: =+Production!S16*Injection!$S$2 -> 0 | T16: =+Production!T16*$T$2 -> 0 | U16: =+Production!U16*$U$2 -> 0 | V16: =+Production!V16*$V$2 -> 0 | W16: =+Production!W16*$W$2 -> 0 | X16: =+Production!X16*$X$2 -> 0 | Y16: =+Production!Y16*$Y$2 -> 0 | Z16: =+Production!Z16*$Z$2 -> 0 | AA16: =+Production!AA16*$AA$2 -> 0 | AB16: =+Production!AB16*$AB$2 -> 0 | AL16: =+Production!AO16*Injection!$AL$2 -> 0 | AM16: =+Production!AP16*Injection!$AM$2 -> 0 | AN16: =+Production!AQ16*$AN$2 -> 1188 | AO16: =+Production!AR16*$AO$2 -> 1200 | AP16: =+Production!AS16*$AP$2 -> 0 | AQ16: =+Production!AT16*$AQ$2 -> 0 | AR16: =+Production!AU16*$AR$2 -> 0 | AS16: =+Production!AV16*$AS$2 -> 0 | AT16: =+Production!AW16*$AT$2 -> 0 | AU16: =+Production!AX16*$AU$2 -> 0 | AV16: =+Production!AY16*$AV$2 -> 0 | AW16: =+Production!AZ16*$AW$2 -> 0 | AX16: =+Production!BA16*$AX$2 -> 0 | AY16: =+Production!BB16*$AY$2 -> 0 | BP16: =+P16+AT16 -> 0 | BQ16: =+Q16+AU16 -> 0 | BR16: =R16+AV16 -> 0 | BS16: =S16+AW16 -> 0 | BT16: =T16+AX16 -> 0 | BU16: =U16+AY16 -> 0 | CK16: =+BA16 -> 0 | CL16: =+BB16 -> 0
A17: 2026/02 | B17: =SUM(D17:BJ17) -> 0 | D17: =+Production!D17*Injection!$D$2 -> 0 | E17: =+Production!E17*Injection!$E$2 -> 0 | F17: =+Production!F17*Injection!$F$2 -> 0 | G17: =+Production!G17*Injection!$G$2 -> 0 | H17: =+Production!H17*Injection!$H$2 -> 0 | I17: =+Production!I17*Injection!$I$2 -> 0 | J17: =+Production!J17*Injection!$J$2 -> 0 | K17: =+Production!K17*Injection!$K$2 -> 0 | L17: =+Production!L17*Injection!$L$2 -> 0 | M17: =+Production!M17*Injection!$M$2 -> 0 | N17: =+Production!N17*Injection!$N$2 -> 0 | O17: =+Production!O17*Injection!$O$2 -> 0 | P17: =+Production!P17*Injection!$P$2 -> 0 | Q17: =+Production!Q17*Injection!$Q$2 -> 0 | R17: =+Production!R17*Injection!$R$2 -> 0 | S17: =+Production!S17*Injection!$S$2 -> 0 | T17: =+Production!T17*$T$2 -> 0 | U17: =+Production!U17*$U$2 -> 0 | V17: =+Production!V17*$V$2 -> 0 | W17: =+Production!W17*$W$2 -> 0 | X17: =+Production!X17*$X$2 -> 0 | Y17: =+Production!Y17*$Y$2 -> 0 | Z17: =+Production!Z17*$Z$2 -> 0 | AA17: =+Production!AA17*$AA$2 -> 0 | AB17: =+Production!AB17*$AB$2 -> 0 | AL17: =+Production!AO17*Injection!$AL$2 -> 0 | AM17: =+Production!AP17*Injection!$AM$2 -> 0 | AN17: =+Production!AQ17*$AN$2 -> 0 | AO17: =+Production!AR17*$AO$2 -> 0 | AP17: =+Production!AS17*$AP$2 -> 0 | AQ17: =+Production!AT17*$AQ$2 -> 0 | AR17: =+Production!AU17*$AR$2 -> 0 | AS17: =+Production!AV17*$AS$2 -> 0 | AT17: =+Production!AW17*$AT$2 -> 0 | AU17: =+Production!AX17*$AU$2 -> 0 | AV17: =+Production!AY17*$AV$2 -> 0 | AW17: =+Production!AZ17*$AW$2 -> 0 | AX17: =+Production!BA17*$AX$2 -> 0 | AY17: =+Production!BB17*$AY$2 -> 0 | BP17: =+P17+AT17 -> 0 | BQ17: =+Q17+AU17 -> 0 | BR17: =R17+AV17 -> 0 | BS17: =S17+AW17 -> 0 | BT17: =T17+AX17 -> 0 | BU17: =U17+AY17 -> 0 | CK17: =+BA17 -> 0 | CL17: =+BB17 -> 0
A18: 2026/03 | B18: =SUM(D18:BJ18) -> 6754.8 | D18: =+Production!D18*Injection!$D$2 -> 0 | E18: =+Production!E18*Injection!$E$2 -> 0 | F18: =+Production!F18*Injection!$F$2 -> 1950 | G18: =+Production!G18*Injection!$G$2 -> 1170 | H18: =+Production!H18*Injection!$H$2 -> 1950 | I18: =+Production!I18*Injection!$I$2 -> 0 | J18: =+Production!J18*Injection!$J$2 -> 0 | K18: =+Production!K18*Injection!$K$2 -> 187.2 | L18: =+Production!L18*Injection!$L$2 -> 0 | M18: =+Production!M18*Injection!$M$2 -> 0 | N18: =+Production!N18*Injection!$N$2 -> 0 | O18: =+Production!O18*Injection!$O$2 -> 0 | P18: =+Production!P18*Injection!$P$2 -> 187.2 | Q18: =+Production!Q18*Injection!$Q$2 -> 187.2 | R18: =+Production!R18*Injection!$R$2 -> 280.8 | S18: =+Production!S18*Injection!$S$2 -> 280.8 | T18: =+Production!T18*$T$2 -> 280.8 | U18: =+Production!U18*$U$2 -> 280.8 | V18: =+Production!V18*$V$2 -> 0 | W18: =+Production!W18*$W$2 -> 0 | X18: =+Production!X18*$X$2 -> 0 | Y18: =+Production!Y18*$Y$2 -> 0 | Z18: =+Production!Z18*$Z$2 -> 0 | AA18: =+Production!AA18*$AA$2 -> 0 | AB18: =+Production!AB18*$AB$2 -> 0 | AL18: =+Production!AO18*Injection!$AL$2 -> 0 | AM18: =+Production!AP18*Injection!$AM$2 -> 0 | AN18: =+Production!AQ18*$AN$2 -> 0 | AO18: =+Production!AR18*$AO$2 -> 0 | AP18: =+Production!AS18*$AP$2 -> 0 | AQ18: =+Production!AT18*$AQ$2 -> 0 | AR18: =+Production!AU18*$AR$2 -> 0 | AS18: =+Production!AV18*$AS$2 -> 0 | AT18: =+Production!AW18*$AT$2 -> 0 | AU18: =+Production!AX18*$AU$2 -> 0 | AV18: =+Production!AY18*$AV$2 -> 0 | AW18: =+Production!AZ18*$AW$2 -> 0 | AX18: =+Production!BA18*$AX$2 -> 0 | AY18: =+Production!BB18*$AY$2 -> 0 | BP18: =+P18+AT18 -> 187.2 | BQ18: =+Q18+AU18 -> 187.2 | BR18: =R18+AV18 -> 280.8 | BS18: =S18+AW18 -> 280.8 | BT18: =T18+AX18 -> 280.8 | BU18: =U18+AY18 -> 280.8 | CK18: =+BA18 -> 0 | CL18: =+BB18 -> 0
A19: 2026/04 | B19: =SUM(D19:BJ19) -> 5428.8 | D19: =+Production!D19*Injection!$D$2 -> 0 | E19: =+Production!E19*Injection!$E$2 -> 0 | F19: =+Production!F19*Injection!$F$2 -> 1248 | G19: =+Production!G19*Injection!$G$2 -> 748.8 | H19: =+Production!H19*Injection!$H$2 -> 1248 | I19: =+Production!I19*Injection!$I$2 -> 0 | J19: =+Production!J19*Injection!$J$2 -> 0 | K19: =+Production!K19*Injection!$K$2 -> 624 | L19: =+Production!L19*Injection!$L$2 -> 0 | M19: =+Production!M19*Injection!$M$2 -> 0 | N19: =+Production!N19*Injection!$N$2 -> 0 | O19: =+Production!O19*Injection!$O$2 -> 0 | P19: =+Production!P19*Injection!$P$2 -> 218.4 | Q19: =+Production!Q19*Injection!$Q$2 -> 218.4 | R19: =+Production!R19*Injection!$R$2 -> 280.8 | S19: =+Production!S19*Injection!$S$2 -> 280.8 | T19: =+Production!T19*$T$2 -> 280.8 | U19: =+Production!U19*$U$2 -> 280.8 | V19: =+Production!V19*$V$2 -> 0 | W19: =+Production!W19*$W$2 -> 0 | X19: =+Production!X19*$X$2 -> 0 | Y19: =+Production!Y19*$Y$2 -> 0 | Z19: =+Production!Z19*$Z$2 -> 0 | AA19: =+Production!AA19*$AA$2 -> 0 | AB19: =+Production!AB19*$AB$2 -> 0 | AL19: =+Production!AO19*Injection!$AL$2 -> 0 | AM19: =+Production!AP19*Injection!$AM$2 -> 0 | AN19: =+Production!AQ19*$AN$2 -> 0 | AO19: =+Production!AR19*$AO$2 -> 0 | AP19: =+Production!AS19*$AP$2 -> 0 | AQ19: =+Production!AT19*$AQ$2 -> 0 | AR19: =+Production!AU19*$AR$2 -> 0 | AS19: =+Production!AV19*$AS$2 -> 0 | AT19: =+Production!AW19*$AT$2 -> 0 | AU19: =+Production!AX19*$AU$2 -> 0 | AV19: =+Production!AY19*$AV$2 -> 0 | AW19: =+Production!AZ19*$AW$2 -> 0 | AX19: =+Production!BA19*$AX$2 -> 0 | AY19: =+Production!BB19*$AY$2 -> 0 | BP19: =+P19+AT19 -> 218.4 | BQ19: =+Q19+AU19 -> 218.4 | BR19: =R19+AV19 -> 280.8 | BS19: =S19+AW19 -> 280.8 | BT19: =T19+AX19 -> 280.8 | BU19: =U19+AY19 -> 280.8 | CK19: =+BA19 -> 0 | CL19: =+BB19 -> 0
A20: 2026/05 | B20: =SUM(D20:BJ20) -> 13115.6 | D20: =+Production!D20*Injection!$D$2 -> 0 | E20: =+Production!E20*Injection!$E$2 -> 0 | F20: =+Production!F20*Injection!$F$2 -> 2730 | G20: =+Production!G20*Injection!$G$2 -> 1638 | H20: =+Production!H20*Injection!$H$2 -> 2730 | I20: =+Production!I20*Injection!$I$2 -> 0 | J20: =+Production!J20*Injection!$J$2 -> 0 | K20: =+Production!K20*Injection!$K$2 -> 873.6 | L20: =+Production!L20*Injection!$L$2 -> 0 | M20: =+Production!M20*Injection!$M$2 -> 0 | N20: =+Production!N20*Injection!$N$2 -> 0 | O20: =+Production!O20*Injection!$O$2 -> 0 | P20: =+Production!P20*Injection!$P$2 -> 156 | Q20: =+Production!Q20*Injection!$Q$2 -> 156 | R20: =+Production!R20*Injection!$R$2 -> 468 | S20: =+Production!S20*Injection!$S$2 -> 468 | T20: =+Production!T20*$T$2 -> 468 | U20: =+Production!U20*$U$2 -> 468 | V20: =+Production!V20*$V$2 -> 0 | W20: =+Production!W20*$W$2 -> 0 | X20: =+Production!X20*$X$2 -> 0 | Y20: =+Production!Y20*$Y$2 -> 0 | Z20: =+Production!Z20*$Z$2 -> 0 | AA20: =+Production!AA20*$AA$2 -> 0 | AB20: =+Production!AB20*$AB$2 -> 0 | AL20: =+Production!AO20*Injection!$AL$2 -> 0 | AM20: =+Production!AP20*Injection!$AM$2 -> 0 | AN20: =+Production!AQ20*$AN$2 -> 0 | AO20: =+Production!AR20*$AO$2 -> 0 | AP20: =+Production!AS20*$AP$2 -> 1296 | AQ20: =+Production!AT20*$AQ$2 -> 1664 | AR20: =+Production!AU20*$AR$2 -> 0 | AS20: =+Production!AV20*$AS$2 -> 0 | AT20: =+Production!AW20*$AT$2 -> 0 | AU20: =+Production!AX20*$AU$2 -> 0 | AV20: =+Production!AY20*$AV$2 -> 0 | AW20: =+Production!AZ20*$AW$2 -> 0 | AX20: =+Production!BA20*$AX$2 -> 0 | AY20: =+Production!BB20*$AY$2 -> 0 | BP20: =+P20+AT20 -> 156 | BQ20: =+Q20+AU20 -> 156 | BR20: =R20+AV20 -> 468 | BS20: =S20+AW20 -> 468 | BT20: =T20+AX20 -> 468 | BU20: =U20+AY20 -> 468 | CK20: =+BA20 -> 0 | CL20: =+BB20 -> 0
... A45: 2026/30 | B45: =SUM(D45:BJ45) -> 26044.4 | D45: =+Production!D45*Injection!$D$2 -> 4368 | E45: =+Production!E45*Injection!$E$2 -> 4633.2 | F45: =+Production!F45*Injection!$F$2 -> 1326 | G45: =+Production!G45*Injection!$G$2 -> 795.6 | H45: =+Production!H45*Injection!$H$2 -> 1326 | I45: =+Production!I45*Injection!$I$2 -> 0 | J45: =+Production!J45*Injection!$J$2 -> 0 | K45: =+Production!K45*Injection!$K$2 -> 811.2 | L45: =+Production!L45*Injection!$L$2 -> 842.4 | M45: =+Production!M45*Injection!$M$2 -> 702 | N45: =+Production!N45*Injection!$N$2 -> 468 | O45: =+Production!O45*Injection!$O$2 -> 312 | P45: =+Production!P45*Injection!$P$2 -> 0 | Q45: =+Production!Q45*Injection!$Q$2 -> 0 | R45: =+Production!R45*Injection!$R$2 -> 0 | S45: =+Production!S45*Injection!$S$2 -> 0 | T45: =+Production!T45*$T$2 -> 0 | U45: =+Production!U45*$U$2 -> 0 | V45: =+Production!V45*$V$2 -> 1029.6 | W45: =+Production!W45*$W$2 -> 764.4 | X45: =+Production!X45*$X$2 -> 764.4 | Y45: =+Production!Y45*$Y$2 -> 327.6 | Z45: =+Production!Z45*$Z$2 -> 327.6 | AA45: =+Production!AA45*$AA$2 -> 655.2 | AB45: =+Production!AB45*$AB$2 -> 655.2 | AL45: =+Production!AO45*Injection!$AL$2 -> 0 | AM45: =+Production!AP45*Injection!$AM$2 -> 0 | AN45: =+Production!AQ45*$AN$2 -> 0 | AO45: =+Production!AR45*$AO$2 -> 0 | AP45: =+Production!AS45*$AP$2 -> 3024 | AQ45: =+Production!AT45*$AQ$2 -> 2912 | AR45: =+Production!AU45*$AR$2 -> 0 | AS45: =+Production!AV45*$AS$2 -> 0 | AT45: =+Production!AW45*$AT$2 -> 0 | AU45: =+Production!AX45*$AU$2 -> 0 | AV45: =+Production!AY45*$AV$2 -> 0 | AW45: =+Production!AZ45*$AW$2 -> 0 | AX45: =+Production!BA45*$AX$2 -> 0 | AY45: =+Production!BB45*$AY$2 -> 0 | BP45: =+P45+AT45 -> 0 | BQ45: =+Q45+AU45 -> 0 | BR45: =R45+AV45 -> 0 | BS45: =S45+AW45 -> 0 | BT45: =T45+AX45 -> 0 | BU45: =U45+AY45 -> 0 | CK45: =+BA45 -> 0 | CL45: =+BB45 -> 0
A46: 2026/31 | B46: =SUM(D46:BJ46) -> 18718.8 | C46: =B46 -> 18718.8 | D46: =+Production!D46*Injection!$D$2 -> 249.6 | E46: =+Production!E46*Injection!$E$2 -> 280.8 | F46: =+Production!F46*Injection!$F$2 -> 0 | G46: =+Production!G46*Injection!$G$2 -> 0 | H46: =+Production!H46*Injection!$H$2 -> 0 | I46: =+Production!I46*Injection!$I$2 -> 0 | J46: =+Production!J46*Injection!$J$2 -> 0 | K46: =+Production!K46*Injection!$K$2 -> 62.4 | L46: =+Production!L46*Injection!$L$2 -> 0 | M46: =+Production!M46*Injection!$M$2 -> 0 | N46: =+Production!N46*Injection!$N$2 -> 0 | O46: =+Production!O46*Injection!$O$2 -> 0 | P46: =+Production!P46*Injection!$P$2 -> 0 | Q46: =+Production!Q46*Injection!$Q$2 -> 0 | R46: =+Production!R46*Injection!$R$2 -> 936 | S46: =+Production!S46*Injection!$S$2 -> 936 | T46: =+Production!T46*$T$2 -> 936 | U46: =+Production!U46*$U$2 -> 936 | V46: =+Production!V46*$V$2 -> 702 | W46: =+Production!W46*$W$2 -> 0 | X46: =+Production!X46*$X$2 -> 0 | Y46: =+Production!Y46*$Y$2 -> 0 | Z46: =+Production!Z46*$Z$2 -> 0 | AA46: =+Production!AA46*$AA$2 -> 0 | AB46: =+Production!AB46*$AB$2 -> 0 | AL46: =+Production!AO46*Injection!$AL$2 -> 0 | AM46: =+Production!AP46*Injection!$AM$2 -> 0 | AN46: =+Production!AQ46*$AN$2 -> 0 | AO46: =+Production!AR46*$AO$2 -> 0 | AP46: =+Production!AS46*$AP$2 -> 3024 | AQ46: =+Production!AT46*$AQ$2 -> 2496 | AR46: =+Production!AU46*$AR$2 -> 0 | AS46: =+Production!AV46*$AS$2 -> 2736 | AT46: =+Production!AW46*$AT$2 -> 0 | AU46: =+Production!AX46*$AU$2 -> 0 | AV46: =+Production!AY46*$AV$2 -> 1200 | AW46: =+Production!AZ46*$AW$2 -> 1512 | AX46: =+Production!BA46*$AX$2 -> 1200 | AY46: =+Production!BB46*$AY$2 -> 1512 | BP46: =+P46+AT46 -> 0 | BQ46: =+Q46+AU46 -> 0 | BR46: =R46+AV46 -> 2136 | BS46: =S46+AW46 -> 2448 | BT46: =T46+AX46 -> 2136 | BU46: =U46+AY46 -> 2448 | CK46: =+BA46 -> 0 | CL46: =+BB46 -> 0
A47: 2026/32 | B47: =SUM(D47:BJ47) -> 35768.4 | C47: =B47 -> 35768.4 | D47: =+Production!D47*Injection!$D$2 -> 7737.6 | E47: =+Production!E47*Injection!$E$2 -> 8424 | F47: =+Production!F47*Injection!$F$2 -> 1716 | G47: =+Production!G47*Injection!$G$2 -> 795.6 | H47: =+Production!H47*Injection!$H$2 -> 1326 | I47: =+Production!I47*Injection!$I$2 -> 0 | J47: =+Production!J47*Injection!$J$2 -> 0 | K47: =+Production!K47*Injection!$K$2 -> 1435.2 | L47: =+Production!L47*Injection!$L$2 -> 2059.2 | M47: =+Production!M47*Injection!$M$2 -> 1716 | N47: =+Production!N47*Injection!$N$2 -> 187.2 | O47: =+Production!O47*Injection!$O$2 -> 124.8 | P47: =+Production!P47*Injection!$P$2 -> 0 | Q47: =+Production!Q47*Injection!$Q$2 -> 0 | R47: =+Production!R47*Injection!$R$2 -> 468 | S47: =+Production!S47*Injection!$S$2 -> 468 | T47: =+Production!T47*$T$2 -> 468 | U47: =+Production!U47*$U$2 -> 468 | V47: =+Production!V47*$V$2 -> 2854.8 | W47: =+Production!W47*$W$2 -> 0 | X47: =+Production!X47*$X$2 -> 0 | Y47: =+Production!Y47*$Y$2 -> 0 | Z47: =+Production!Z47*$Z$2 -> 0 | AA47: =+Production!AA47*$AA$2 -> 0 | AB47: =+Production!AB47*$AB$2 -> 0 | AL47: =+Production!AO47*Injection!$AL$2 -> 0 | AM47: =+Production!AP47*Injection!$AM$2 -> 0 | AN47: =+Production!AQ47*$AN$2 -> 0 | AO47: =+Production!AR47*$AO$2 -> 0 | AP47: =+Production!AS47*$AP$2 -> 3024 | AQ47: =+Production!AT47*$AQ$2 -> 2496 | AR47: =+Production!AU47*$AR$2 -> 0 | AS47: =+Production!AV47*$AS$2 -> 0 | AT47: =+Production!AW47*$AT$2 -> 0 | AU47: =+Production!AX47*$AU$2 -> 0 | AV47: =+Production!AY47*$AV$2 -> 0 | AW47: =+Production!AZ47*$AW$2 -> 0 | AX47: =+Production!BA47*$AX$2 -> 0 | AY47: =+Production!BB47*$AY$2 -> 0 | BP47: =+P47+AT47 -> 0 | BQ47: =+Q47+AU47 -> 0 | BR47: =R47+AV47 -> 468 | BS47: =S47+AW47 -> 468 | BT47: =T47+AX47 -> 468 | BU47: =U47+AY47 -> 468 | CK47: =+BA47 -> 0 | CL47: =+BB47 -> 0
A48: 2026/33 | B48: =SUM(D48:BJ48) -> 34701.6 | C48: =B48 -> 34701.6 | D48: =+Production!D48*Injection!$D$2 -> 1622.4 | E48: =+Production!E48*Injection!$E$2 -> 1825.2 | F48: =+Production!F48*Injection!$F$2 -> 1716 | G48: =+Production!G48*Injection!$G$2 -> 1310.4 | H48: =+Production!H48*Injection!$H$2 -> 2106 | I48: =+Production!I48*Injection!$I$2 -> 0 | J48: =+Production!J48*Injection!$J$2 -> 0 | K48: =+Production!K48*Injection!$K$2 -> 811.2 | L48: =+Production!L48*Injection!$L$2 -> 0 | M48: =+Production!M48*Injection!$M$2 -> 0 | N48: =+Production!N48*Injection!$N$2 -> 748.8 | O48: =+Production!O48*Injection!$O$2 -> 499.2 | P48: =+Production!P48*Injection!$P$2 -> 0 | Q48: =+Production!Q48*Injection!$Q$2 -> 0 | R48: =+Production!R48*Injection!$R$2 -> 1029.6 | S48: =+Production!S48*Injection!$S$2 -> 1029.6 | T48: =+Production!T48*$T$2 -> 1029.6 | U48: =+Production!U48*$U$2 -> 1029.6 | V48: =+Production!V48*$V$2 -> 1778.4 | W48: =+Production!W48*$W$2 -> 2511.6 | X48: =+Production!X48*$X$2 -> 2074.8 | Y48: =+Production!Y48*$Y$2 -> 889.2 | Z48: =+Production!Z48*$Z$2 -> 889.2 | AA48: =+Production!AA48*$AA$2 -> 2152.8 | AB48: =+Production!AB48*$AB$2 -> 1872 | AL48: =+Production!AO48*Injection!$AL$2 -> 0 | AM48: =+Production!AP48*Injection!$AM$2 -> 0 | AN48: =+Production!AQ48*$AN$2 -> 0 | AO48: =+Production!AR48*$AO$2 -> 0 | AP48: =+Production!AS48*$AP$2 -> 3024 | AQ48: =+Production!AT48*$AQ$2 -> 2496 | AR48: =+Production!AU48*$AR$2 -> 0 | AS48: =+Production!AV48*$AS$2 -> 0 | AT48: =+Production!AW48*$AT$2 -> 0 | AU48: =+Production!AX48*$AU$2 -> 0 | AV48: =+Production!AY48*$AV$2 -> 480 | AW48: =+Production!AZ48*$AW$2 -> 648 | AX48: =+Production!BA48*$AX$2 -> 480 | AY48: =+Production!BB48*$AY$2 -> 648 | BP48: =+P48+AT48 -> 0 | BQ48: =+Q48+AU48 -> 0 | BR48: =R48+AV48 -> 1509.6 | BS48: =S48+AW48 -> 1677.6 | BT48: =T48+AX48 -> 1509.6 | BU48: =U48+AY48 -> 1677.6 | CK48: =+BA48 -> 0 | CL48: =+BB48 -> 0
A49: 2026/34 | B49: =SUM(D49:BJ49) -> 18980.8 | C49: =B49 -> 18980.8 | D49: =+Production!D49*Injection!$D$2 -> 0 | E49: =+Production!E49*Injection!$E$2 -> 0 | F49: =+Production!F49*Injection!$F$2 -> 0 | G49: =+Production!G49*Injection!$G$2 -> 0 | H49: =+Production!H49*Injection!$H$2 -> 0 | I49: =+Production!I49*Injection!$I$2 -> 0 | J49: =+Production!J49*Injection!$J$2 -> 0 | K49: =+Production!K49*Injection!$K$2 -> 0 | L49: =+Production!L49*Injection!$L$2 -> 1591.2 | M49: =+Production!M49*Injection!$M$2 -> 1326 | N49: =+Production!N49*Injection!$N$2 -> 0 | O49: =+Production!O49*Injection!$O$2 -> 0 | P49: =+Production!P49*Injection!$P$2 -> 312 | Q49: =+Production!Q49*Injection!$Q$2 -> 312 | R49: =+Production!R49*Injection!$R$2 -> 0 | S49: =+Production!S49*Injection!$S$2 -> 0 | T49: =+Production!T49*$T$2 -> 0 | U49: =+Production!U49*$U$2 -> 0 | V49: =+Production!V49*$V$2 -> 0 | W49: =+Production!W49*$W$2 -> 1528.8 | X49: =+Production!X49*$X$2 -> 1528.8 | Y49: =+Production!Y49*$Y$2 -> 655.2 | Z49: =+Production!Z49*$Z$2 -> 655.2 | AA49: =+Production!AA49*$AA$2 -> 1216.8 | AB49: =+Production!AB49*$AB$2 -> 1216.8 | AL49: =+Production!AO49*Injection!$AL$2 -> 0 | AM49: =+Production!AP49*Injection!$AM$2 -> 0 | AN49: =+Production!AQ49*$AN$2 -> 0 | AO49: =+Production!AR49*$AO$2 -> 0 | AP49: =+Production!AS49*$AP$2 -> 3024 | AQ49: =+Production!AT49*$AQ$2 -> 2496 | AR49: =+Production!AU49*$AR$2 -> 0 | AS49: =+Production!AV49*$AS$2 -> 0 | AT49: =+Production!AW49*$AT$2 -> 432 | AU49: =+Production!AX49*$AU$2 -> 430 | AV49: =+Production!AY49*$AV$2 -> 480 | AW49: =+Production!AZ49*$AW$2 -> 648 | AX49: =+Production!BA49*$AX$2 -> 480 | AY49: =+Production!BB49*$AY$2 -> 648 | BP49: =+P49+AT49 -> 744 | BQ49: =+Q49+AU49 -> 742 | BR49: =R49+AV49 -> 480 | BS49: =S49+AW49 -> 648 | BT49: =T49+AX49 -> 480 | BU49: =U49+AY49 -> 648 | CK49: =+BA49 -> 0 | CL49: =+BB49 -> 0
A50: 2026/35 | B50: =SUM(D50:BJ50) -> 23548.4 | C50: =B50 -> 23548.4 | D50: =+Production!D50*Injection!$D$2 -> 0 | E50: =+Production!E50*Injection!$E$2 -> 0 | F50: =+Production!F50*Injection!$F$2 -> 1794 | G50: =+Production!G50*Injection!$G$2 -> 1076.4 | H50: =+Production!H50*Injection!$H$2 -> 1794 | I50: =+Production!I50*Injection!$I$2 -> 0 | J50: =+Production!J50*Injection!$J$2 -> 0 | K50: =+Production!K50*Injection!$K$2 -> 998.4 | L50: =+Production!L50*Injection!$L$2 -> 0 | M50: =+Production!M50*Injection!$M$2 -> 0 | N50: =+Production!N50*Injection!$N$2 -> 0 | O50: =+Production!O50*Injection!$O$2 -> 0 | P50: =+Production!P50*Injection!$P$2 -> 0 | Q50: =+Production!Q50*Injection!$Q$2 -> 0 | R50: =+Production!R50*Injection!$R$2 -> 655.2 | S50: =+Production!S50*Injection!$S$2 -> 748.8 | T50: =+Production!T50*$T$2 -> 748.8 | U50: =+Production!U50*$U$2 -> 748.8 | V50: =+Production!V50*$V$2 -> 2761.2 | W50: =+Production!W50*$W$2 -> 2184 | X50: =+Production!X50*$X$2 -> 873.6 | Y50: =+Production!Y50*$Y$2 -> 374.4 | Z50: =+Production!Z50*$Z$2 -> 327.6 | AA50: =+Production!AA50*$AA$2 -> 1778.4 | AB50: =+Production!AB50*$AB$2 -> 748.8 | AL50: =+Production!AO50*Injection!$AL$2 -> 0 | AM50: =+Production!AP50*Injection!$AM$2 -> 0 | AN50: =+Production!AQ50*$AN$2 -> 0 | AO50: =+Production!AR50*$AO$2 -> 0 | AP50: =+Production!AS50*$AP$2 -> 3024 | AQ50: =+Production!AT50*$AQ$2 -> 2912 | AR50: =+Production!AU50*$AR$2 -> 0 | AS50: =+Production!AV50*$AS$2 -> 0 | AT50: =+Production!AW50*$AT$2 -> 0 | AU50: =+Production!AX50*$AU$2 -> 0 | AV50: =+Production!AY50*$AV$2 -> 0 | AW50: =+Production!AZ50*$AW$2 -> 0 | AX50: =+Production!BA50*$AX$2 -> 0 | AY50: =+Production!BB50*$AY$2 -> 0 | BP50: =+P50+AT50 -> 0 | BQ50: =+Q50+AU50 -> 0 | BR50: =R50+AV50 -> 655.2 | BS50: =S50+AW50 -> 748.8 | BT50: =T50+AX50 -> 748.8 | BU50: =U50+AY50 -> 748.8 | CK50: =+BA50 -> 0 | CL50: =+BB50 -> 0
A51: 2026/36 | B51: =SUM(D51:BJ51) -> 15576.8 | C51: =B51 -> 15576.8 | D51: =+Production!D51*Injection!$D$2 -> 0 | E51: =+Production!E51*Injection!$E$2 -> 0 | F51: =+Production!F51*Injection!$F$2 -> 858 | G51: =+Production!G51*Injection!$G$2 -> 514.8 | H51: =+Production!H51*Injection!$H$2 -> 858 | I51: =+Production!I51*Injection!$I$2 -> 0 | J51: =+Production!J51*Injection!$J$2 -> 0 | K51: =+Production!K51*Injection!$K$2 -> 499.2 | L51: =+Production!L51*Injection!$L$2 -> 1497.6 | M51: =+Production!M51*Injection!$M$2 -> 1248 | N51: =+Production!N51*Injection!$N$2 -> 0 | O51: =+Production!O51*Injection!$O$2 -> 0 | P51: =+Production!P51*Injection!$P$2 -> 187.2 | Q51: =+Production!Q51*Injection!$Q$2 -> 187.2 | R51: =+Production!R51*Injection!$R$2 -> 842.4 | S51: =+Production!S51*Injection!$S$2 -> 748.8 | T51: =+Production!T51*$T$2 -> 748.8 | U51: =+Production!U51*$U$2 -> 748.8 | V51: =+Production!V51*$V$2 -> 702 | W51: =+Production!W51*$W$2 -> 0 | X51: =+Production!X51*$X$2 -> 0 | Y51: =+Production!Y51*$Y$2 -> 0 | Z51: =+Production!Z51*$Z$2 -> 0 | AA51: =+Production!AA51*$AA$2 -> 0 | AB51: =+Production!AB51*$AB$2 -> 0 | AL51: =+Production!AO51*Injection!$AL$2 -> 0 | AM51: =+Production!AP51*Injection!$AM$2 -> 0 | AN51: =+Production!AQ51*$AN$2 -> 0 | AO51: =+Production!AR51*$AO$2 -> 0 | AP51: =+Production!AS51*$AP$2 -> 3024 | AQ51: =+Production!AT51*$AQ$2 -> 2912 | AR51: =+Production!AU51*$AR$2 -> 0 | AS51: =+Production!AV51*$AS$2 -> 0 | AT51: =+Production!AW51*$AT$2 -> 0 | AU51: =+Production!AX51*$AU$2 -> 0 | AV51: =+Production!AY51*$AV$2 -> 0 | AW51: =+Production!AZ51*$AW$2 -> 0 | AX51: =+Production!BA51*$AX$2 -> 0 | AY51: =+Production!BB51*$AY$2 -> 0 | BP51: =+P51+AT51 -> 187.2 | BQ51: =+Q51+AU51 -> 187.2 | BR51: =R51+AV51 -> 842.4 | BS51: =S51+AW51 -> 748.8 | BT51: =T51+AX51 -> 748.8 | BU51: =U51+AY51 -> 748.8 | CK51: =+BA51 -> 0 | CL51: =+BB51 -> 0
A52: 2026/37 | B52: =SUM(D52:BJ52) -> 14722 | C52: =B52 -> 14722 | D52: =+Production!D52*Injection!$D$2 -> 0 | E52: =+Production!E52*Injection!$E$2 -> 0 | F52: =+Production!F52*Injection!$F$2 -> 312 | G52: =+Production!G52*Injection!$G$2 -> 280.8 | H52: =+Production!H52*Injection!$H$2 -> 468 | I52: =+Production!I52*Injection!$I$2 -> 0 | J52: =+Production!J52*Injection!$J$2 -> 0 | K52: =+Production!K52*Injection!$K$2 -> 499.2 | L52: =+Production!L52*Injection!$L$2 -> 187.2 | M52: =+Production!M52*Injection!$M$2 -> 156 | N52: =+Production!N52*Injection!$N$2 -> 0 | O52: =+Production!O52*Injection!$O$2 -> 0 | P52: =+Production!P52*Injection!$P$2 -> 0 | Q52: =+Production!Q52*Injection!$Q$2 -> 0 | R52: =+Production!R52*Injection!$R$2 -> 93.6 | S52: =+Production!S52*Injection!$S$2 -> 93.6 | T52: =+Production!T52*$T$2 -> 93.6 | U52: =+Production!U52*$U$2 -> 93.6 | V52: =+Production!V52*$V$2 -> 2293.2 | W52: =+Production!W52*$W$2 -> 327.6 | X52: =+Production!X52*$X$2 -> 327.6 | Y52: =+Production!Y52*$Y$2 -> 0 | Z52: =+Production!Z52*$Z$2 -> 0 | AA52: =+Production!AA52*$AA$2 -> 0 | AB52: =+Production!AB52*$AB$2 -> 0 | AL52: =+Production!AO52*Injection!$AL$2 -> 0 | AM52: =+Production!AP52*Injection!$AM$2 -> 0 | AN52: =+Production!AQ52*$AN$2 -> 0 | AO52: =+Production!AR52*$AO$2 -> 0 | AP52: =+Production!AS52*$AP$2 -> 1728 | AQ52: =+Production!AT52*$AQ$2 -> 2912 | AR52: =+Production!AU52*$AR$2 -> 0 | AS52: =+Production!AV52*$AS$2 -> 0 | AT52: =+Production!AW52*$AT$2 -> 432 | AU52: =+Production!AX52*$AU$2 -> 344 | AV52: =+Production!AY52*$AV$2 -> 960 | AW52: =+Production!AZ52*$AW$2 -> 1080 | AX52: =+Production!BA52*$AX$2 -> 960 | AY52: =+Production!BB52*$AY$2 -> 1080 | BP52: =+P52+AT52 -> 432 | BQ52: =+Q52+AU52 -> 344 | BR52: =R52+AV52 -> 1053.6 | BS52: =S52+AW52 -> 1173.6 | BT52: =T52+AX52 -> 1053.6 | BU52: =U52+AY52 -> 1173.6 | CK52: =+BA52 -> 0 | CL52: =+BB52 -> 0
A53: 2026/38 | B53: =SUM(D53:BJ53) -> 12888.4 | C53: =B53 -> 12888.4 | D53: =+Production!D53*Injection!$D$2 -> 0 | E53: =+Production!E53*Injection!$E$2 -> 0 | F53: =+Production!F53*Injection!$F$2 -> 468 | G53: =+Production!G53*Injection!$G$2 -> 140.4 | H53: =+Production!H53*Injection!$H$2 -> 234 | I53: =+Production!I53*Injection!$I$2 -> 0 | J53: =+Production!J53*Injection!$J$2 -> 0 | K53: =+Production!K53*Injection!$K$2 -> 936 | L53: =+Production!L53*Injection!$L$2 -> 748.8 | M53: =+Production!M53*Injection!$M$2 -> 624 | N53: =+Production!N53*Injection!$N$2 -> 0 | O53: =+Production!O53*Injection!$O$2 -> 0 | P53: =+Production!P53*Injection!$P$2 -> 0 | Q53: =+Production!Q53*Injection!$Q$2 -> 0 | R53: =+Production!R53*Injection!$R$2 -> 280.8 | S53: =+Production!S53*Injection!$S$2 -> 280.8 | T53: =+Production!T53*$T$2 -> 280.8 | U53: =+Production!U53*$U$2 -> 280.8 | V53: =+Production!V53*$V$2 -> 1263.6 | W53: =+Production!W53*$W$2 -> 1092 | X53: =+Production!X53*$X$2 -> 0 | Y53: =+Production!Y53*$Y$2 -> 187.2 | Z53: =+Production!Z53*$Z$2 -> 187.2 | AA53: =+Production!AA53*$AA$2 -> 936 | AB53: =+Production!AB53*$AB$2 -> 0 | AL53: =+Production!AO53*Injection!$AL$2 -> 0 | AM53: =+Production!AP53*Injection!$AM$2 -> 0 | AN53: =+Production!AQ53*$AN$2 -> 0 | AO53: =+Production!AR53*$AO$2 -> 0 | AP53: =+Production!AS53*$AP$2 -> 0 | AQ53: =+Production!AT53*$AQ$2 -> 0 | AR53: =+Production!AU53*$AR$2 -> 0 | AS53: =+Production!AV53*$AS$2 -> 0 | AT53: =+Production!AW53*$AT$2 -> 216 | AU53: =+Production!AX53*$AU$2 -> 172 | AV53: =+Production!AY53*$AV$2 -> 1200 | AW53: =+Production!AZ53*$AW$2 -> 1080 | AX53: =+Production!BA53*$AX$2 -> 1200 | AY53: =+Production!BB53*$AY$2 -> 1080 | BP53: =+P53+AT53 -> 216 | BQ53: =+Q53+AU53 -> 172 | BR53: =R53+AV53 -> 1480.8 | BS53: =S53+AW53 -> 1360.8 | BT53: =T53+AX53 -> 1480.8 | BU53: =U53+AY53 -> 1360.8 | CK53: =+BA53 -> 0 | CL53: =+BB53 -> 0
A54: 2026/39 | B54: =SUM(D54:BJ54) -> 14942.4 | C54: =B54 -> 14942.4 | D54: =+Production!D54*Injection!$D$2 -> 0 | E54: =+Production!E54*Injection!$E$2 -> 0 | F54: =+Production!F54*Injection!$F$2 -> 702 | G54: =+Production!G54*Injection!$G$2 -> 421.2 | H54: =+Production!H54*Injection!$H$2 -> 702 | I54: =+Production!I54*Injection!$I$2 -> 0 | J54: =+Production!J54*Injection!$J$2 -> 0 | K54: =+Production!K54*Injection!$K$2 -> 1310.4 | L54: =+Production!L54*Injection!$L$2 -> 0 | M54: =+Production!M54*Injection!$M$2 -> 0 | N54: =+Production!N54*Injection!$N$2 -> 0 | O54: =+Production!O54*Injection!$O$2 -> 0 | P54: =+Production!P54*Injection!$P$2 -> 218.4 | Q54: =+Production!Q54*Injection!$Q$2 -> 218.4 | R54: =+Production!R54*Injection!$R$2 -> 1404 | S54: =+Production!S54*Injection!$S$2 -> 1404 | T54: =+Production!T54*$T$2 -> 1404 | U54: =+Production!U54*$U$2 -> 1404 | V54: =+Production!V54*$V$2 -> 234 | W54: =+Production!W54*$W$2 -> 0 | X54: =+Production!X54*$X$2 -> 0 | Y54: =+Production!Y54*$Y$2 -> 0 | Z54: =+Production!Z54*$Z$2 -> 0 | AA54: =+Production!AA54*$AA$2 -> 0 | AB54: =+Production!AB54*$AB$2 -> 0 | AL54: =+Production!AO54*Injection!$AL$2 -> 0 | AM54: =+Production!AP54*Injection!$AM$2 -> 0 | AN54: =+Production!AQ54*$AN$2 -> 0 | AO54: =+Production!AR54*$AO$2 -> 0 | AP54: =+Production!AS54*$AP$2 -> 3024 | AQ54: =+Production!AT54*$AQ$2 -> 2496 | AR54: =+Production!AU54*$AR$2 -> 0 | AS54: =+Production!AV54*$AS$2 -> 0 | AT54: =+Production!AW54*$AT$2 -> 0 | AU54: =+Production!AX54*$AU$2 -> 0 | AV54: =+Production!AY54*$AV$2 -> 0 | AW54: =+Production!AZ54*$AW$2 -> 0 | AX54: =+Production!BA54*$AX$2 -> 0 | AY54: =+Production!BB54*$AY$2 -> 0 | BP54: =+P54+AT54 -> 218.4 | BQ54: =+Q54+AU54 -> 218.4 | BR54: =R54+AV54 -> 1404 | BS54: =S54+AW54 -> 1404 | BT54: =T54+AX54 -> 1404 | BU54: =U54+AY54 -> 1404 | CK54: =+BA54 -> 0 | CL54: =+BB54 -> 0
