Workbook

Sheet Breakdown 
B2: KS
B3: Italy | E3: Mexico | H3: Argentina | K3: Brazil | N3: TOTAL KS
A4: Dest. Code | B4: LPIA | E4: MXPA | H4: ARPA | K4: ARPA
A5: Item | B5: BARBIE FOOTBALL | C5: BARBIE BASKETBALL | D5: BARBIE CRICKET | E5: BARBIE FOOTBALL | F5: BARBIE BASKETBALL | G5: BARBIE CRICKET | H5: BARBIE FOOTBALL | I5: BARBIE BASKETBALL | J5: BARBIE CRICKET | K5: BARBIE FOOTBALL | L5: BARBIE BASKETBALL | M5: BARBIE CRICKET
A6: MPG | B6: VZ275 | C6: VZ276 | D6: VZ280 | E6: VZ275 | F6: VZ276 | G6: VZ280 | H6: VZ275 | I6: VZ276 | J6: VZ280 | K6: VZ275 | L6: VZ276 | M6: VZ280 | N6: VZ275 | O6: VZ276 | P6: VZ280
A7: Version: | B7: INTERNATIONAL | C7: INTERNATIONAL | D7: INTERNATIONAL | E7: EC-Inte | F7: EC-Inte | G7: EC-Inte | H7: EC-Inte | I7: EC-Inte | J7: EC-Inte | K7: EC-BRA | L7: EC-BRA | M7: EC-BRA
A8: PCS/carton
A9: confirm | B9: 202.8 | C9: 202.8 | D9: 202.8 | E9: 982.8 | F9: 982.8 | G9: 982.8 | H9: 468 | I9: 468 | J9: 468 | K9: 811.2 | L9: 811.2 | M9: 811.2 | N9: =+B9+E9+H9+K9 -> 2464.8 | O9: =+C9+F9+I9+L9 -> 2464.8 | P9: =+D9+G9+J9+M9 -> 2464.8
A10: Option | B10: 201 | C10: 201 | D10: 201 | E10: 982 | F10: 982 | G10: 982 | H10: 465 | I10: 465 | J10: 465 | K10: 802 | L10: 802 | M10: 802 | N10: =+B10+E10+H10+K10 -> 2450 | O10: =+C10+F10+I10+L10 -> 2450 | P10: =+D10+G10+J10+M10 -> 2450
A11: Total | B11: =B9+B10 -> 403.8 | C11: =C9+C10 -> 403.8 | D11: =D9+D10 -> 403.8 | E11: =E9+E10 -> 1964.8 | F11: =F9+F10 -> 1964.8 | G11: =G9+G10 -> 1964.8 | H11: =H9+H10 -> 933 | I11: =I9+I10 -> 933 | ... P11: =P9+P10 -> 4914.8
A12: Industrial Code: | B12: 79064826 | C12: 79064828 | D12: 79064836 | E12: 79064826 | F12: 79064828 | G12: 79064836 | H12: 79064826 | I12: 79064828 | J12: 79064836 | K12: 79064827 | L12: 79064829 | M12: 79064837
A13: capsule color | B13: Senft | C13: Senft | D13: Senft | E13: Senft | F13: Senft | G13: Senft | H13: Senft | I13: Senft | J13: Senft | K13: Transparent | L13: Transparent | M13: Transparent
A14: 2026/42 | B14: 0 | C14: 0 | D14: 0 | E14: 0 | F14: 0 | G14: 0 | H14: 0 | I14: 0 | J14: 0 | K14: 0 | L14: 0 | M14: 0 | N14: =+B14+E14+K14+H14 -> 0 | O14: =+C14+F14+L14+I14 -> 0 | P14: =+D14+G14+M14+J14 -> 0
A15: 2026/43 | B15: 0 | C15: 0 | D15: 0 | E15: 0 | F15: 0 | G15: 0 | H15: 0 | I15: 0 | J15: 0 | K15: 0 | L15: 0 | M15: 0 | N15: =+B15+E15+K15+H15 -> 0 | O15: =+C15+F15+L15+I15 -> 0 | P15: =+D15+G15+M15+J15 -> 0
A16: 2026/44 | B16: 0 | C16: 0 | D16: 0 | E16: 0 | F16: 0 | G16: 0 | H16: 0 | I16: 0 | J16: 0 | K16: 0 | L16: 0 | M16: 0 | N16: =+B16+E16+K16+H16 -> 0 | O16: =+C16+F16+L16+I16 -> 0 | P16: =+D16+G16+M16+J16 -> 0
A17: 2026/45 | B17: 0 | C17: 0 | D17: 0 | E17: 0 | F17: 0 | G17: 0 | H17: 0 | I17: 0 | J17: 0 | K17: 0 | L17: 0 | M17: 0 | N17: =+B17+E17+K17+H17 -> 0 | O17: =+C17+F17+L17+I17 -> 0 | P17: =+D17+G17+M17+J17 -> 0
A18: 2026/46 | B18: 0 | C18: 0 | D18: 0 | E18: 0 | F18: 0 | G18: 0 | H18: 0 | I18: 0 | J18: 0 | K18: 0 | L18: 0 | M18: 0 | N18: =+B18+E18+K18+H18 -> 0 | O18: =+C18+F18+L18+I18 -> 0 | P18: =+D18+G18+M18+J18 -> 0
A19: 2026/47 | B19: 0 | C19: 0 | D19: 0 | E19: 0 | F19: 0 | G19: 0 | H19: 0 | I19: 0 | J19: 0 | K19: 0 | L19: 0 | M19: 0 | N19: =+B19+E19+K19+H19 -> 0 | O19: =+C19+F19+L19+I19 -> 0 | P19: =+D19+G19+M19+J19 -> 0
A20: 2026/48 | B20: 0 | C20: 0 | D20: 0 | E20: 0 | F20: 0 | G20: 0 | H20: 0 | I20: 0 | J20: 0 | K20: 0 | L20: 0 | M20: 0 | N20: =+B20+E20+K20+H20 -> 0 | O20: =+C20+F20+L20+I20 -> 0 | P20: =+D20+G20+M20+J20 -> 0
A21: 2026/49 | B21: 0 | C21: 0 | D21: 0 | E21: 0 | F21: 0 | G21: 0 | H21: 0 | I21: 0 | J21: 0 | K21: 0 | L21: 0 | M21: 0 | N21: =+B21+E21+K21+H21 -> 0 | O21: =+C21+F21+L21+I21 -> 0 | P21: =+D21+G21+M21+J21 -> 0
A22: 2026/50 | B22: 0 | C22: 0 | D22: 0 | E22: 0 | F22: 0 | G22: 0 | H22: 0 | I22: 0 | J22: 0 | K22: 0 | L22: 0 | M22: 0 | N22: =+B22+E22+K22+H22 -> 0 | O22: =+C22+F22+L22+I22 -> 0 | P22: =+D22+G22+M22+J22 -> 0
A23: 2026/51 | B23: 0 | C23: 0 | D23: 0 | E23: 0 | F23: 0 | G23: 0 | H23: 0 | I23: 0 | J23: 0 | K23: 0 | L23: 0 | M23: 0 | N23: =+B23+E23+K23+H23 -> 0 | O23: =+C23+F23+L23+I23 -> 0 | P23: =+D23+G23+M23+J23 -> 0
A24: 2026/52 | B24: 0 | C24: 0 | D24: 0 | E24: 0 | F24: 0 | G24: 0 | H24: 0 | I24: 0 | J24: 0 | K24: 0 | L24: 0 | M24: 0 | N24: =+B24+E24+K24+H24 -> 0 | O24: =+C24+F24+L24+I24 -> 0 | P24: =+D24+G24+M24+J24 -> 0
A25: 2026/53 | B25: 0 | C25: 0 | D25: 0 | E25: 0 | F25: 0 | G25: 0 | H25: 0 | I25: 0 | J25: 0 | K25: 0 | L25: 0 | M25: 0 | N25: =+B25+E25+K25+H25 -> 0 | O25: =+C25+F25+L25+I25 -> 0 | P25: =+D25+G25+M25+J25 -> 0
... A77: 2027/52 | B77: 0 | C77: 0 | D77: 0 | E77: 0 | F77: 0 | G77: 0 | H77: 0 | I77: 0 | J77: 0 | K77: 0 | L77: 0 | M77: 0 | N77: =+B77+E77+K77+H77 -> 0 | O77: =+C77+F77+L77+I77 -> 0 | P77: =+D77+G77+M77+J77 -> 0
A78: 2028/01 | N78: =+B78+E78+K78+H78 -> 0 | O78: =+C78+F78+L78+I78 -> 0 | P78: =+D78+G78+M78+J78 -> 0
A79: 2028/02 | N79: =+B79+E79+K79+H79 -> 0 | O79: =+C79+F79+L79+I79 -> 0 | P79: =+D79+G79+M79+J79 -> 0
A80: 2028/03 | N80: =+B80+E80+K80+H80 -> 0 | O80: =+C80+F80+L80+I80 -> 0 | P80: =+D80+G80+M80+J80 -> 0
A81: 2028/04 | N81: =+B81+E81+K81+H81 -> 0 | O81: =+C81+F81+L81+I81 -> 0 | P81: =+D81+G81+M81+J81 -> 0
A82: 2028/05 | N82: =+B82+E82+K82+H82 -> 0 | O82: =+C82+F82+L82+I82 -> 0 | P82: =+D82+G82+M82+J82 -> 0
A83: 2028/06 | N83: =+B83+E83+K83+H83 -> 0 | O83: =+C83+F83+L83+I83 -> 0 | P83: =+D83+G83+M83+J83 -> 0
A84: Total | B84: =SUM(B14:B83) -> 405.6 | C84: =SUM(C14:C83) -> 404.8 | D84: =SUM(D14:D83) -> 405.6 | E84: =SUM(E14:E83) -> 1965.6 | F84: =SUM(F14:F83) -> 1965.6 | G84: =SUM(G14:G83) -> 1965.6 | H84: =SUM(H14:H83) -> 936 | I84: =SUM(I14:I83) -> 936 | ... M84: =SUM(M14:M83) -> 1622.4 | N84: =+B84+E84+K84+H84 -> 4929.6 | O84: =+C84+F84+L84+I84 -> 4928.8 | P84: =+D84+G84+M84+J84 -> 4929.6
B85: FALSE | C85: FALSE | D85: FALSE | E85: FALSE | F85: FALSE | G85: FALSE | H85: FALSE | I85: FALSE | J85: FALSE | K85: FALSE | L85: FALSE | M85: FALSE
B86: FALSE | C86: FALSE | D86: FALSE | E86: FALSE | F86: FALSE | G86: FALSE | H86: FALSE | I86: FALSE | J86: FALSE | K86: FALSE | L86: FALSE | M86: FALSE
B87: =B84-B11 -> 1.8 | C87: =C84-C11 -> 1 | D87: =D84-D11 -> 1.8 | E87: =E84-E11 -> 0.8 | F87: =F84-F11 -> 0.8 | G87: =G84-G11 -> 0.8 | H87: =H84-H11 -> 3 | I87: =I84-I11 -> 3 | ... M87: =M84-M11 -> 9.2
B88: 15.6 | C88: 15.6 | D88: 15.6 | E88: 15.6 | F88: 15.6 | G88: 15.6 | H88: 15.6 | I88: 15.6 | J88: 15.6 | K88: 15.6 | L88: 15.6 | M88: 15.6
B89: =+B87<=B88 -> TRUE | C89: =+C87<=C88 -> TRUE | D89: =+D87<=D88 -> TRUE | E89: =+E87<=E88 -> TRUE | F89: =+F87<=F88 -> TRUE | G89: =+G87<=G88 -> TRUE | H89: =+H87<=H88 -> TRUE | I89: =+I87<=I88 -> TRUE | ... M89: =+M87<=M88 -> TRUE

Sheet BARBIE 2728
A3: Past Shipments | B3: BOLD | D3: Supplier : | E3: NIIGATA
A4: Changes | B4: RED | D4: Name of Family : | E4: BARBIE 2728
A5: Train | D5: Requested Weekly Output :
A6: Air | D6: Date: | E6: 45545
B9: Italy | C9: Mexico | D9: Argentina | E9: Brazil | F9: Total (weekly) | G9: CUM (Total) | H9: Date | I9: NR. OF WEEK | J9: ASN NO. | K9: ETD | L9: ETA | M9: MEANS OF TRANSPORT | N9: SHIPPING LINE | O9: VESSEL NAME | P9: NOTE | Q9: CONTAINER NO. | R9: SEAL NO. | S9: INVOICE NO.
B10: LPIA | C10: MXPA | D10: ARPA | E10: ARPA
A11: Version: | B11: INTERNATIONAL | C11: EC-Inte | D11: EC-Inte | E11: EC-BRA
A12: Capsule:
A13: No. of items | B13: 3 | C13: 3 | D13: 3 | E13: 3
A14: Released Qty: | B14: =SUM('Breakdown '!B9:D9) -> 608.4 | C14: =+SUM('Breakdown '!E9:G9) -> 2948.4 | D14: =+SUM('Breakdown '!H9:J9) -> 1404 | E14: =+SUM('Breakdown '!K9:M9) -> 2433.6
A15: Option Qty: | B15: =SUM('Breakdown '!B10:D10) -> 603 | C15: =+SUM('Breakdown '!E10:G10) -> 2946 | D15: =+SUM('Breakdown '!H10:J10) -> 1395 | E15: =+SUM('Breakdown '!K10:M10) -> 2406
A16: TOTAL QTY: | B16: =B15+B14 -> 1211.4 | C16: =C15+C14 -> 5894.4 | D16: =D15+D14 -> 2799 | E16: =E15+E14 -> 4839.6
A17: PO No.
A18: Format | B18: T00 | C18: T00 | D18: T00 | E18: T00
A19: 2026/42 | B19: =+SUM('Breakdown '!B14:D14) -> 0 | C19: =+SUM('Breakdown '!E14:G14) -> 0 | D19: =+SUM('Breakdown '!H14:J14) -> 0 | E19: =+SUM('Breakdown '!K14:M14) -> 0 | F19: =SUM(B19:E19) -> 0 | G19: 0 | H19: 46308 | I19: =_xlfn.ISOWEEKNUM(H19) -> 42
A20: 2026/43 | B20: =+SUM('Breakdown '!B15:D15) -> 0 | C20: =+SUM('Breakdown '!E15:G15) -> 0 | D20: =+SUM('Breakdown '!H15:J15) -> 0 | E20: =+SUM('Breakdown '!K15:M15) -> 0 | F20: =SUM(B20:E20) -> 0 | G20: =F20+G19 -> 0 | H20: =H19+7 -> 46315 | I20: =_xlfn.ISOWEEKNUM(H20) -> 43
A21: 2026/44 | B21: =+SUM('Breakdown '!B16:D16) -> 0 | C21: =+SUM('Breakdown '!E16:G16) -> 0 | D21: =+SUM('Breakdown '!H16:J16) -> 0 | E21: =+SUM('Breakdown '!K16:M16) -> 0 | F21: =SUM(B21:E21) -> 0 | G21: =F21+G20 -> 0 | H21: =H20+7 -> 46322 | I21: =_xlfn.ISOWEEKNUM(H21) -> 44
A22: 2026/45 | B22: =+SUM('Breakdown '!B17:D17) -> 0 | C22: =+SUM('Breakdown '!E17:G17) -> 0 | D22: =+SUM('Breakdown '!H17:J17) -> 0 | E22: =+SUM('Breakdown '!K17:M17) -> 0 | F22: =SUM(B22:E22) -> 0 | G22: =F22+G21 -> 0 | H22: =H21+7 -> 46329 | I22: =_xlfn.ISOWEEKNUM(H22) -> 45
A23: 2026/46 | B23: =+SUM('Breakdown '!B18:D18) -> 0 | C23: =+SUM('Breakdown '!E18:G18) -> 0 | D23: =+SUM('Breakdown '!H18:J18) -> 0 | E23: =+SUM('Breakdown '!K18:M18) -> 0 | F23: =SUM(B23:E23) -> 0 | G23: =F23+G22 -> 0 | H23: =H22+7 -> 46336 | I23: =_xlfn.ISOWEEKNUM(H23) -> 46
A24: 2026/47 | B24: =+SUM('Breakdown '!B19:D19) -> 0 | C24: =+SUM('Breakdown '!E19:G19) -> 0 | D24: =+SUM('Breakdown '!H19:J19) -> 0 | E24: =+SUM('Breakdown '!K19:M19) -> 0 | F24: =SUM(B24:E24) -> 0 | G24: =F24+G23 -> 0 | H24: =H23+7 -> 46343 | I24: =_xlfn.ISOWEEKNUM(H24) -> 47
A25: 2026/48 | B25: =+SUM('Breakdown '!B20:D20) -> 0 | C25: =+SUM('Breakdown '!E20:G20) -> 0 | D25: =+SUM('Breakdown '!H20:J20) -> 0 | E25: =+SUM('Breakdown '!K20:M20) -> 0 | F25: =SUM(B25:E25) -> 0 | G25: =F25+G24 -> 0 | H25: =H24+7 -> 46350 | I25: =_xlfn.ISOWEEKNUM(H25) -> 48
A26: 2026/49 | B26: =+SUM('Breakdown '!B21:D21) -> 0 | C26: =+SUM('Breakdown '!E21:G21) -> 0 | D26: =+SUM('Breakdown '!H21:J21) -> 0 | E26: =+SUM('Breakdown '!K21:M21) -> 0 | F26: =SUM(B26:E26) -> 0 | G26: =F26+G25 -> 0 | H26: =H25+7 -> 46357 | I26: =_xlfn.ISOWEEKNUM(H26) -> 49
A27: 2026/50 | B27: =+SUM('Breakdown '!B22:D22) -> 0 | C27: =+SUM('Breakdown '!E22:G22) -> 0 | D27: =+SUM('Breakdown '!H22:J22) -> 0 | E27: =+SUM('Breakdown '!K22:M22) -> 0 | F27: =SUM(B27:E27) -> 0 | G27: =F27+G26 -> 0 | H27: =H26+7 -> 46364 | I27: =_xlfn.ISOWEEKNUM(H27) -> 50
A28: 2026/51 | B28: =+SUM('Breakdown '!B23:D23) -> 0 | C28: =+SUM('Breakdown '!E23:G23) -> 0 | D28: =+SUM('Breakdown '!H23:J23) -> 0 | E28: =+SUM('Breakdown '!K23:M23) -> 0 | F28: =SUM(B28:E28) -> 0 | G28: =F28+G27 -> 0 | H28: =H27+7 -> 46371 | I28: =_xlfn.ISOWEEKNUM(H28) -> 51
A29: 2026/52 | B29: =+SUM('Breakdown '!B24:D24) -> 0 | C29: =+SUM('Breakdown '!E24:G24) -> 0 | D29: =+SUM('Breakdown '!H24:J24) -> 0 | E29: =+SUM('Breakdown '!K24:M24) -> 0 | F29: =SUM(B29:E29) -> 0 | G29: =F29+G28 -> 0 | H29: =H28+7 -> 46378 | I29: =_xlfn.ISOWEEKNUM(H29) -> 52
A30: 2026/53 | B30: =+SUM('Breakdown '!B25:D25) -> 0 | C30: =+SUM('Breakdown '!E25:G25) -> 0 | D30: =+SUM('Breakdown '!H25:J25) -> 0 | E30: =+SUM('Breakdown '!K25:M25) -> 0 | F30: =SUM(B30:E30) -> 0 | G30: =F30+G29 -> 0 | H30: =H29+7 -> 46385 | I30: =_xlfn.ISOWEEKNUM(H30) -> 53
A31: 2027/01 | B31: =+SUM('Breakdown '!B26:D26) -> 0 | C31: =+SUM('Breakdown '!E26:G26) -> 0 | D31: =+SUM('Breakdown '!H26:J26) -> 0 | E31: =+SUM('Breakdown '!K26:M26) -> 0 | F31: =SUM(B31:E31) -> 0 | G31: =F31+G30 -> 0 | H31: =H30+7 -> 46392 | I31: =_xlfn.ISOWEEKNUM(H31) -> 1
... A51: 2027/21 | B51: =+SUM('Breakdown '!B46:D46) -> 0 | C51: =+SUM('Breakdown '!E46:G46) -> 0 | D51: =+SUM('Breakdown '!H46:J46) -> 0 | E51: =+SUM('Breakdown '!K46:M46) -> 936 | F51: =SUM(B51:E51) -> 936 | G51: =F51+G50 -> 12026.8 | H51: =H50+7 -> 46532 | I51: =_xlfn.ISOWEEKNUM(H51) -> 21
A52: 2027/22 | B52: =+SUM('Breakdown '!B47:D47) -> 0 | C52: =+SUM('Breakdown '!E47:G47) -> 702 | D52: =+SUM('Breakdown '!H47:J47) -> 234 | E52: =+SUM('Breakdown '!K47:M47) -> 0 | F52: =SUM(B52:E52) -> 936 | G52: =F52+G51 -> 12962.8 | H52: 45831 | I52: =_xlfn.ISOWEEKNUM(H52) -> 26
A53: 2027/23 | B53: =+SUM('Breakdown '!B48:D48) -> 0 | C53: =+SUM('Breakdown '!E48:G48) -> 0 | D53: =+SUM('Breakdown '!H48:J48) -> 327.6 | E53: =+SUM('Breakdown '!K48:M48) -> 608.4 | F53: =SUM(B53:E53) -> 936 | G53: =F53+G52 -> 13898.8 | H53: =H51+7 -> 46539 | I53: =_xlfn.ISOWEEKNUM(H53) -> 22
A54: 2027/24 | B54: =+SUM('Breakdown '!B49:D49) -> 0 | C54: =+SUM('Breakdown '!E49:G49) -> 0 | D54: =+SUM('Breakdown '!H49:J49) -> 0 | E54: =+SUM('Breakdown '!K49:M49) -> 889.2 | F54: =SUM(B54:E54) -> 889.2 | G54: =F54+G53 -> 14788 | H54: =H53+7 -> 46546 | I54: =_xlfn.ISOWEEKNUM(H54) -> 23
A55: 2027/25 | B55: =+SUM('Breakdown '!B50:D50) -> 0 | C55: =+SUM('Breakdown '!E50:G50) -> 0 | D55: =+SUM('Breakdown '!H50:J50) -> 0 | E55: =+SUM('Breakdown '!K50:M50) -> 0 | F55: =SUM(B55:E55) -> 0 | G55: =F55+G54 -> 14788 | H55: =H54+7 -> 46553 | I55: =_xlfn.ISOWEEKNUM(H55) -> 24
A56: 2027/26 | B56: =+SUM('Breakdown '!B51:D51) -> 0 | C56: =+SUM('Breakdown '!E51:G51) -> 0 | D56: =+SUM('Breakdown '!H51:J51) -> 0 | E56: =+SUM('Breakdown '!K51:M51) -> 0 | F56: =SUM(B56:E56) -> 0 | G56: =F56+G55 -> 14788 | H56: =H55+7 -> 46560 | I56: =_xlfn.ISOWEEKNUM(H56) -> 25
A57: 2027/27 | B57: =+SUM('Breakdown '!B52:D52) -> 0 | C57: =+SUM('Breakdown '!E52:G52) -> 0 | D57: =+SUM('Breakdown '!H52:J52) -> 0 | E57: =+SUM('Breakdown '!K52:M52) -> 0 | F57: =SUM(B57:E57) -> 0 | G57: =F57+G56 -> 14788 | H57: =H56+7 -> 46567 | I57: =_xlfn.ISOWEEKNUM(H57) -> 26
A58: 2027/28 | B58: =+SUM('Breakdown '!B53:D53) -> 0 | C58: =+SUM('Breakdown '!E53:G53) -> 0 | D58: =+SUM('Breakdown '!H53:J53) -> 0 | E58: =+SUM('Breakdown '!K53:M53) -> 0 | F58: =SUM(B58:E58) -> 0 | G58: =F58+G57 -> 14788 | H58: =H57+7 -> 46574 | I58: =_xlfn.ISOWEEKNUM(H58) -> 27
A59: 2027/29 | B59: =+SUM('Breakdown '!B54:D54) -> 0 | C59: =+SUM('Breakdown '!E54:G54) -> 0 | D59: =+SUM('Breakdown '!H54:J54) -> 0 | E59: =+SUM('Breakdown '!K54:M54) -> 0 | F59: =SUM(B59:E59) -> 0 | G59: =F59+G58 -> 14788 | H59: =H58+7 -> 46581 | I59: =_xlfn.ISOWEEKNUM(H59) -> 28
A60: 2027/30 | B60: =+SUM('Breakdown '!B55:D55) -> 0 | C60: =+SUM('Breakdown '!E55:G55) -> 0 | D60: =+SUM('Breakdown '!H55:J55) -> 0 | E60: =+SUM('Breakdown '!K55:M55) -> 0 | F60: =SUM(B60:E60) -> 0 | G60: =F60+G59 -> 14788 | H60: =H59+7 -> 46588 | I60: =_xlfn.ISOWEEKNUM(H60) -> 29
A61: 2027/31 | B61: =+SUM('Breakdown '!B56:D56) -> 0 | C61: =+SUM('Breakdown '!E56:G56) -> 0 | D61: =+SUM('Breakdown '!H56:J56) -> 0 | E61: =+SUM('Breakdown '!K56:M56) -> 0 | F61: =SUM(B61:E61) -> 0 | G61: =F61+G60 -> 14788 | H61: =H60+7 -> 46595 | I61: =_xlfn.ISOWEEKNUM(H61) -> 30
A62: 2027/32 | B62: =+SUM('Breakdown '!B57:D57) -> 0 | C62: =+SUM('Breakdown '!E57:G57) -> 0 | D62: =+SUM('Breakdown '!H57:J57) -> 0 | E62: =+SUM('Breakdown '!K57:M57) -> 0 | F62: =SUM(B62:E62) -> 0 | G62: =F62+G61 -> 14788 | H62: =H61+7 -> 46602 | I62: =_xlfn.ISOWEEKNUM(H62) -> 31
A63: 2027/33 | B63: =+SUM('Breakdown '!B58:D58) -> 0 | C63: =+SUM('Breakdown '!E57:G57) -> 0 | D63: =+SUM('Breakdown '!H58:J58) -> 0 | E63: =+SUM('Breakdown '!K58:M58) -> 0 | F63: =SUM(B63:E63) -> 0 | G63: =F63+G62 -> 14788 | H63: =H62+7 -> 46609 | I63: =_xlfn.ISOWEEKNUM(H63) -> 32
...

Sheet Release Qty
A3: 46293
A76: 46079
