Workbook

Sheet Breakdown 
B2: KS
B3: Belgium | E3: Italy | H3: ISRAEL | K3: Poland | N3: Russia | Q3: Mexico | T3: Argentina | W3: TOTAL KS
A4: Dest. Code | B4: LPBA | E4: LPIA | H4: LPIA | K4: LPPA | N4: RUPA | Q4: MXPA | T4: ARPA
A5: Item | B5: BEAVER WOODLAND | C5: MOUSE WOODLAND | D5: RACCOON WOODLAND | E5: BEAVER WOODLAND | F5: MOUSE WOODLAND | G5: RACCOON WOODLAND | H5: BEAVER WOODLAND | I5: MOUSE WOODLAND | J5: RACCOON WOODLAND | K5: BEAVER WOODLAND | L5: MOUSE WOODLAND | M5: RACCOON WOODLAND | N5: BEAVER WOODLAND | O5: MOUSE WOODLAND | P5: RACCOON WOODLAND | Q5: BEAVER WOODLAND | R5: MOUSE WOODLAND | S5: RACCOON WOODLAND | T5: BEAVER WOODLAND | U5: MOUSE WOODLAND | V5: RACCOON WOODLAND
A6: MPG | B6: VZ164 | C6: VZ171 | D6: VZ172 | E6: VZ164 | F6: VZ171 | G6: VZ172 | H6: VZ164 | I6: VZ171 | J6: VZ172 | K6: VZ164 | L6: VZ171 | M6: VZ172 | N6: VZ164 | O6: VZ171 | P6: VZ172 | Q6: VZ164 | R6: VZ171 | S6: VZ172 | T6: VZ164 | U6: VZ171 | V6: VZ172 | W6: VZ164 | X6: VZ171 | Y6: VZ172
A7: Version: | B7: INTERNATIONAL | C7: INTERNATIONAL | D7: INTERNATIONAL | E7: INTERNATIONAL | F7: INTERNATIONAL | G7: INTERNATIONAL | H7: ISRAEL | I7: ISRAEL | J7: ISRAEL | K7: INTERNATIONAL | L7: INTERNATIONAL | M7: INTERNATIONAL | N7: INTERNATIONAL | O7: INTERNATIONAL | P7: INTERNATIONAL | Q7: EC-Inte | R7: EC-Inte | S7: EC-Inte | T7: EC-Inte | U7: EC-Inte | V7: EC-Inte
A8: PCS/carton
A9: confirm | B9: 624 | C9: 624 | D9: 624 | E9: 702 | F9: 702 | G9: 702 | H9: 31.2 | I9: 31.2 | J9: 31.2 | K9: 920.4 | L9: 920.4 | M9: 920.4 | N9: 608.4 | O9: 608.4 | P9: 608.4 | Q9: 234 | R9: 234 | S9: 234 | T9: 15.6 | U9: 15.6 | V9: 15.6 | W9: =+B9+E9+H9+K9+N9+Q9++T9 -> 3135.6 | X9: =+C9+F9+I9+L9+O9+R9++U9 -> 3135.6 | Y9: =+D9+G9+J9+M9+P9+S9++V9 -> 3135.6
A10: Option | B10: 1497 | C10: 1497 | D10: 1497 | E10: 1614 | F10: 1614 | G10: 1614 | H10: 64 | I10: 64 | J10: 64 | K10: 2142 | L10: 2142 | M10: 2142 | N10: 1423 | O10: 1423 | P10: 1423 | Q10: 532 | R10: 532 | S10: 532 | T10: 38 | U10: 38 | V10: 38 | W10: =+B10+E10+H10+K10+N10+Q10++T10 -> 7310 | X10: =+C10+F10+I10+L10+O10+R10++U10 -> 7310 | Y10: =+D10+G10+J10+M10+P10+S10++V10 -> 7310
A11: Total | B11: =B9+B10 -> 2121 | C11: =C9+C10 -> 2121 | D11: =D9+D10 -> 2121 | E11: =E9+E10 -> 2316 | F11: =F9+F10 -> 2316 | G11: =G9+G10 -> 2316 | H11: =H9+H10 -> 95.2 | I11: =I9+I10 -> 95.2 | ... Y11: =Y9+Y10 -> 10445.6
A12: Industrial Code: | B12: 79065338 | C12: 79064001 | D12: 79064011 | E12: 79065338 | F12: 79064001 | G12: 79064011 | H12: 79065340 | I12: 79064003 | J12: 79064013 | K12: 79065338 | L12: 79064001 | M12: 79064011 | N12: 79065338 | O12: 79064001 | P12: 79064011 | Q12: 79065339 | R12: 79064002 | S12: 79064012 | T12: 79065339 | U12: 79064002 | V12: 79064012
A13: capsule color | B13: Senft | C13: Senft | D13: Senft | E13: Senft | F13: Senft | G13: Senft | H13: Senft | I13: Senft | J13: Senft | K13: Senft | L13: Senft | M13: Senft | N13: Senft | O13: Senft | P13: Senft | Q13: Senft | R13: Senft | S13: Senft | T13: Senft | U13: Senft | V13: Senft
A14: 2026/42 | B14: 0 | C14: 0 | D14: 0 | E14: 0 | F14: 0 | G14: 0 | H14: 0 | I14: 0 | J14: 0 | K14: 0 | L14: 0 | M14: 0 | N14: 0 | O14: 0 | P14: 0 | Q14: 0 | R14: 0 | S14: 0 | T14: 0 | U14: 0 | V14: 0 | W14: =+B14+E14+K14+H14+Q14 -> 0 | X14: =+C14+F14+L14+I14+R14 -> 0 | Y14: =+D14+G14+M14+J14+S14 -> 0
A15: 2026/43 | B15: 0 | C15: 0 | D15: 0 | E15: 0 | F15: 0 | G15: 0 | H15: 0 | I15: 0 | J15: 0 | K15: 0 | L15: 0 | M15: 0 | N15: 0 | O15: 0 | P15: 0 | Q15: 0 | R15: 0 | S15: 0 | T15: 0 | U15: 0 | V15: 0 | W15: =+B15+E15+K15+H15+Q15 -> 0 | X15: =+C15+F15+L15+I15+R15 -> 0 | Y15: =+D15+G15+M15+J15+S15 -> 0
A16: 2026/44 | B16: 0 | C16: 0 | D16: 0 | E16: 0 | F16: 0 | G16: 0 | H16: 0 | I16: 0 | J16: 0 | K16: 0 | L16: 0 | M16: 0 | N16: 0 | O16: 0 | P16: 0 | Q16: 0 | R16: 0 | S16: 0 | T16: 0 | U16: 0 | V16: 0 | W16: =+B16+E16+K16+H16+Q16 -> 0 | X16: =+C16+F16+L16+I16+R16 -> 0 | Y16: =+D16+G16+M16+J16+S16 -> 0
A17: 2026/45 | B17: 0 | C17: 0 | D17: 0 | E17: 0 | F17: 0 | G17: 0 | H17: 0 | I17: 0 | J17: 0 | K17: 0 | L17: 0 | M17: 0 | N17: 0 | O17: 0 | P17: 0 | Q17: 0 | R17: 0 | S17: 0 | T17: 0 | U17: 0 | V17: 0 | W17: =+B17+E17+K17+H17+Q17 -> 0 | X17: =+C17+F17+L17+I17+R17 -> 0 | Y17: =+D17+G17+M17+J17+S17 -> 0
A18: 2026/46 | B18: 0 | C18: 0 | D18: 0 | E18: 0 | F18: 0 | G18: 0 | H18: 0 | I18: 0 | J18: 0 | K18: 0 | L18: 0 | M18: 0 | N18: 0 | O18: 0 | P18: 0 | Q18: 0 | R18: 0 | S18: 0 | T18: 0 | U18: 0 | V18: 0 | W18: =+B18+E18+K18+H18+Q18 -> 0 | X18: =+C18+F18+L18+I18+R18 -> 0 | Y18: =+D18+G18+M18+J18+S18 -> 0
A19: 2026/47 | B19: 0 | C19: 0 | D19: 0 | E19: 0 | F19: 0 | G19: 0 | H19: 0 | I19: 0 | J19: 0 | K19: 0 | L19: 0 | M19: 0 | N19: 0 | O19: 0 | P19: 0 | Q19: 0 | R19: 0 | S19: 0 | T19: 0 | U19: 0 | V19: 0 | W19: =+B19+E19+K19+H19+Q19 -> 0 | X19: =+C19+F19+L19+I19+R19 -> 0 | Y19: =+D19+G19+M19+J19+S19 -> 0
A20: 2026/48 | B20: 0 | C20: 0 | D20: 0 | E20: 46.8 | F20: 46.8 | G20: 46.8 | H20: 0 | I20: 0 | J20: 0 | K20: 0 | L20: 0 | M20: 0 | N20: 0 | O20: 0 | P20: 0 | Q20: 0 | R20: 0 | S20: 0 | T20: 0 | U20: 0 | V20: 0 | W20: =+B20+E20+K20+H20+Q20 -> 46.8 | X20: =+C20+F20+L20+I20+R20 -> 46.8 | Y20: =+D20+G20+M20+J20+S20 -> 46.8
A21: 2026/49 | B21: 0 | C21: 0 | D21: 0 | E21: 0 | F21: 0 | G21: 0 | H21: 0 | I21: 0 | J21: 0 | K21: 156 | L21: 156 | M21: 156 | N21: 0 | O21: 0 | P21: 0 | Q21: 0 | R21: 0 | S21: 0 | T21: 0 | U21: 0 | V21: 0 | W21: =+B21+E21+K21+H21+Q21 -> 156 | X21: =+C21+F21+L21+I21+R21 -> 156 | Y21: =+D21+G21+M21+J21+S21 -> 156
A22: 2026/50 | B22: 156 | C22: 156 | D22: 156 | E22: 0 | F22: 0 | G22: 0 | H22: 0 | I22: 0 | J22: 0 | K22: 0 | L22: 0 | M22: 0 | N22: 0 | O22: 0 | P22: 0 | Q22: 0 | R22: 0 | S22: 0 | T22: 0 | U22: 0 | V22: 0 | W22: =+B22+E22+K22+H22+Q22 -> 156 | X22: =+C22+F22+L22+I22+R22 -> 156 | Y22: =+D22+G22+M22+J22+S22 -> 156
A23: 2026/51 | B23: 0 | C23: 0 | D23: 0 | E23: 156 | F23: 156 | G23: 156 | H23: 0 | I23: 0 | J23: 0 | K23: 0 | L23: 0 | M23: 0 | N23: 0 | O23: 0 | P23: 0 | Q23: 0 | R23: 0 | S23: 0 | T23: 0 | U23: 0 | V23: 0 | W23: =+B23+E23+K23+H23+Q23 -> 156 | X23: =+C23+F23+L23+I23+R23 -> 156 | Y23: =+D23+G23+M23+J23+S23 -> 156
A24: 2026/52 | B24: 0 | C24: 0 | D24: 0 | E24: 0 | F24: 0 | G24: 0 | H24: 0 | I24: 0 | J24: 0 | K24: 249.6 | L24: 249.6 | M24: 249.6 | N24: 0 | O24: 0 | P24: 0 | Q24: 0 | R24: 0 | S24: 0 | T24: 0 | U24: 0 | V24: 0 | W24: =+B24+E24+K24+H24+Q24 -> 249.6 | X24: =+C24+F24+L24+I24+R24 -> 249.6 | Y24: =+D24+G24+M24+J24+S24 -> 249.6
A25: 2026/53 | B25: 124.8 | C25: 124.8 | D25: 124.8 | E25: 0 | F25: 0 | G25: 0 | H25: 0 | I25: 0 | J25: 0 | N25: 0 | O25: 0 | P25: 0 | Q25: 0 | R25: 0 | S25: 0 | T25: 0 | U25: 0 | V25: 0 | W25: =+B25+E25+K25+H25+Q25 -> 124.8 | X25: =+C25+F25+L25+I25+R25 -> 124.8 | Y25: =+D25+G25+M25+J25+S25 -> 124.8
A26: 2027/01 | B26: 156 | C26: 156 | D26: 156 | E26: 234 | F26: 234 | G26: 234 | H26: 0 | I26: 0 | J26: 0 | K26: 0 | L26: 0 | M26: 0 | N26: 0 | O26: 0 | P26: 0 | Q26: 0 | R26: 0 | S26: 0 | T26: 0 | U26: 0 | V26: 0 | W26: =+B26+E26+K26+H26+Q26 -> 390 | X26: =+C26+F26+L26+I26+R26 -> 390 | Y26: =+D26+G26+M26+J26+S26 -> 390
A27: 2027/02 | B27: 0 | C27: 0 | D27: 0 | E27: 249.6 | F27: 249.6 | G27: 249.6 | H27: 0 | I27: 0 | J27: 0 | K27: 0 | L27: 0 | M27: 0 | N27: 0 | O27: 0 | P27: 0 | Q27: 0 | R27: 0 | S27: 0 | T27: 0 | U27: 0 | V27: 0 | W27: =+B27+E27+K27+H27+Q27 -> 249.6 | X27: =+C27+F27+L27+I27+R27 -> 249.6 | Y27: =+D27+G27+M27+J27+S27 -> 249.6
A28: 2027/03 | B28: 0 | C28: 0 | D28: 0 | E28: 93.6 | F28: 93.6 | G28: 93.6 | H28: 0 | I28: 0 | J28: 0 | K28: 249.6 | L28: 249.6 | M28: 249.6 | N28: 0 | O28: 0 | P28: 0 | Q28: 0 | R28: 0 | S28: 0 | T28: 0 | U28: 0 | V28: 0 | W28: =+B28+E28+K28+H28+Q28 -> 343.2 | X28: =+C28+F28+L28+I28+R28 -> 343.2 | Y28: =+D28+G28+M28+J28+S28 -> 343.2
A29: 2027/04 | B29: 187.2 | C29: 187.2 | D29: 187.2 | E29: 0 | F29: 0 | G29: 0 | H29: 31.2 | I29: 31.2 | J29: 31.2 | K29: 0 | L29: 0 | M29: 0 | N29: 0 | O29: 0 | P29: 0 | Q29: 0 | R29: 0 | S29: 0 | T29: 0 | U29: 0 | V29: 0 | W29: =+B29+E29+K29+H29+Q29 -> 218.4 | X29: =+C29+F29+L29+I29+R29 -> 218.4 | Y29: =+D29+G29+M29+J29+S29 -> 218.4
A30: 2027/05 | B30: 0 | C30: 0 | D30: 0 | E30: 0 | F30: 0 | G30: 0 | H30: 0 | I30: 0 | J30: 0 | K30: 0 | L30: 0 | M30: 0 | N30: 0 | O30: 0 | P30: 0 | Q30: 0 | R30: 0 | S30: 0 | T30: 0 | U30: 0 | V30: 0 | W30: =+B30+E30+K30+H30+Q30 -> 0 | X30: =+C30+F30+L30+I30+R30 -> 0 | Y30: =+D30+G30+M30+J30+S30 -> 0
A31: 2027/06 | B31: 0 | C31: 0 | D31: 0 | E31: 0 | F31: 0 | G31: 0 | H31: 0 | I31: 0 | J31: 0 | K31: 0 | L31: 0 | M31: 0 | N31: 0 | O31: 0 | P31: 0 | Q31: 0 | R31: 0 | S31: 0 | T31: 0 | U31: 0 | V31: 0 | W31: =+B31+E31+K31+H31+Q31 -> 0 | X31: =+C31+F31+L31+I31+R31 -> 0 | Y31: =+D31+G31+M31+J31+S31 -> 0
A32: 2027/07 | B32: 0 | C32: 0 | D32: 0 | E32: 171.6 | F32: 171.6 | G32: 171.6 | H32: 31.2 | I32: 31.2 | J32: 31.2 | K32: 93.6 | L32: 93.6 | M32: 93.6 | N32: 0 | O32: 0 | P32: 0 | Q32: 0 | R32: 0 | S32: 0 | T32: 0 | U32: 0 | V32: 0 | W32: =+B32+E32+K32+H32+Q32 -> 296.4 | X32: =+C32+F32+L32+I32+R32 -> 296.4 | Y32: =+D32+G32+M32+J32+S32 -> 296.4
A33: 2027/08 | B33: 156 | C33: 156 | D33: 156 | E33: 0 | F33: 0 | G33: 0 | K33: 171.6 | L33: 171.6 | M33: 171.6 | N33: 0 | O33: 0 | P33: 0 | Q33: 0 | R33: 0 | S33: 0 | T33: 0 | U33: 0 | V33: 0 | W33: =+B33+E33+K33+H33+Q33 -> 327.6 | X33: =+C33+F33+L33+I33+R33 -> 327.6 | Y33: =+D33+G33+M33+J33+S33 -> 327.6
A34: 2027/09 | B34: 202.8 | C34: 202.8 | D34: 202.8 | E34: 0 | F34: 0 | G34: 0 | K34: 93.6 | L34: 93.6 | M34: 93.6 | N34: 0 | O34: 0 | P34: 0 | Q34: 0 | R34: 0 | S34: 0 | T34: 0 | U34: 0 | V34: 0 | W34: =+B34+E34+K34+H34+Q34 -> 296.4 | X34: =+C34+F34+L34+I34+R34 -> 296.4 | Y34: =+D34+G34+M34+J34+S34 -> 296.4
A35: 2027/10 | B35: 234 | C35: 234 | D35: 234 | E35: 0 | F35: 0 | G35: 0 | K35: 0 | L35: 0 | M35: 0 | N35: 0 | O35: 0 | P35: 0 | Q35: 0 | R35: 0 | S35: 0 | T35: 0 | U35: 0 | V35: 0 | W35: =+B35+E35+K35+H35+Q35 -> 234 | X35: =+C35+F35+L35+I35+R35 -> 234 | Y35: =+D35+G35+M35+J35+S35 -> 234
A36: 2027/11 | B36: 0 | C36: 0 | D36: 0 | E36: 0 | F36: 0 | G36: 0 | K36: 249.6 | L36: 249.6 | M36: 249.6 | N36: 0 | O36: 0 | P36: 0 | Q36: 0 | R36: 0 | S36: 0 | T36: 0 | U36: 0 | V36: 0 | W36: =+B36+E36+K36+H36+Q36 -> 249.6 | X36: =+C36+F36+L36+I36+R36 -> 249.6 | Y36: =+D36+G36+M36+J36+S36 -> 249.6
A37: 2027/12 | B37: 0 | C37: 0 | D37: 0 | E37: 280.8 | F37: 280.8 | G37: 280.8 | K37: 0 | L37: 0 | M37: 0 | N37: 0 | O37: 0 | P37: 0 | Q37: 0 | R37: 0 | S37: 0 | T37: 0 | U37: 0 | V37: 0 | W37: =+B37+E37+K37+H37+Q37 -> 280.8 | X37: =+C37+F37+L37+I37+R37 -> 280.8 | Y37: =+D37+G37+M37+J37+S37 -> 280.8
A38: 2027/13 | B38: 78 | C38: 78 | D38: 78 | E38: 109.2 | F38: 109.2 | G38: 109.2 | K38: 0 | L38: 0 | M38: 0 | N38: 0 | O38: 0 | P38: 0 | Q38: 234 | R38: 234 | S38: 234 | T38: 15.6 | U38: 15.6 | V38: 15.6 | W38: =+B38+E38+K38+H38+Q38 -> 421.2 | X38: =+C38+F38+L38+I38+R38 -> 421.2 | Y38: =+D38+G38+M38+J38+S38 -> 421.2
A39: 2027/14 | B39: 0 | C39: 0 | D39: 0 | E39: 234 | F39: 234 | G39: 234 | K39: 62.4 | L39: 62.4 | M39: 62.4 | N39: 0 | O39: 0 | P39: 0 | Q39: 0 | R39: 0 | S39: 0 | T39: 0 | U39: 0 | V39: 0 | W39: =+B39+E39+K39+H39+Q39 -> 296.4 | X39: =+C39+F39+L39+I39+R39 -> 296.4 | Y39: =+D39+G39+M39+J39+S39 -> 296.4
A40: 2027/15 | B40: 171.8 | C40: 171.8 | D40: 171.8 | E40: 0 | F40: 0 | G40: 0 | K40: 156 | L40: 156 | M40: 156 | N40: 0 | O40: 0 | P40: 0 | Q40: 0 | R40: 0 | S40: 0 | T40: 0 | U40: 0 | V40: 0 | W40: =+B40+E40+K40+H40+Q40 -> 327.8 | X40: =+C40+F40+L40+I40+R40 -> 327.8 | Y40: =+D40+G40+M40+J40+S40 -> 327.8
A41: 2027/16 | B41: 0 | C41: 0 | D41: 0 | E41: 0 | F41: 0 | G41: 0 | K41: 280.8 | L41: 280.8 | M41: 280.8 | N41: 0 | O41: 0 | P41: 0 | Q41: 0 | R41: 0 | S41: 0 | T41: 0 | U41: 0 | V41: 0 | W41: =+B41+E41+K41+H41+Q41 -> 280.8 | X41: =+C41+F41+L41+I41+R41 -> 280.8 | Y41: =+D41+G41+M41+J41+S41 -> 280.8
...

Sheet NATOONS WOODLAND
A3: Past Shipments | B3: BOLD | D3: Supplier : | E3: NIIGATA
A4: Changes | B4: RED | D4: Name of Family : | E4: NATOONS WOODLAND
A5: Train | D5: Requested Weekly Output :
A6: Air | D6: Date: | E6: 45545
B9: Belgium | C9: Italy | D9: Italy | E9: Poland | F9: Russia | G9: Mexico | H9: Argentina | I9: Total (weekly) | J9: CUM (Total) | K9: Date | L9: NR. OF WEEK | M9: ASN NO. | N9: ETD | O9: ETA | P9: MEANS OF TRANSPORT | Q9: SHIPPING LINE | R9: VESSEL NAME | S9: NOTE | T9: CONTAINER NO. | U9: SEAL NO. | V9: INVOICE NO.
B10: LPBA | C10: LPIA | D10: LPIA | E10: LPPA | F10: RUPA | G10: MXPA | H10: ARPA
A11: Version: | B11: INTERNATIONAL | C11: INTERNATIONAL | D11: ISRAEL | E11: INTERNATIONAL | F11: INTERNATIONAL | G11: EC-Inte | H11: EC-Inte
A12: Capsule:
A13: No. of items | B13: 3 | C13: 3 | D13: 3 | E13: 3 | F13: 3 | G13: 3 | H13: 3
A14: Released Qty: | B14: =SUM('Breakdown '!B9:D9) -> 1872 | C14: =+SUM('Breakdown '!E9:G9) -> 2106 | D14: =+SUM('Breakdown '!H9:J9) -> 93.6 | E14: =+SUM('Breakdown '!K9:M9) -> 2761.2 | F14: =+SUM('Breakdown '!L9:N9) -> 2449.2 | G14: =+SUM('Breakdown '!M9:O9) -> 2137.2 | H14: =+SUM('Breakdown '!N9:P9) -> 1825.2
A15: Option Qty: | B15: =SUM('Breakdown '!B10:D10) -> 4491 | C15: =+SUM('Breakdown '!E10:G10) -> 4842 | D15: =+SUM('Breakdown '!H10:J10) -> 192 | E15: =+SUM('Breakdown '!K10:M10) -> 6426 | F15: =+SUM('Breakdown '!L10:N10) -> 5707 | G15: =+SUM('Breakdown '!M10:O10) -> 4988 | H15: =+SUM('Breakdown '!N10:P10) -> 4269
A16: TOTAL QTY: | B16: =B15+B14 -> 6363 | C16: =C15+C14 -> 6948 | D16: =D15+D14 -> 285.6 | E16: =E15+E14 -> 9187.2 | F16: =F15+F14 -> 8156.2 | G16: =G15+G14 -> 7125.2 | H16: =H15+H14 -> 6094.2
A17: PO No.
A18: Format | B18: T00 | C18: T00 | D18: T00 | E18: T00 | F18: T00 | G18: T00 | H18: T00
A19: 2026/42 | B19: =+SUM('Breakdown '!B14:D14) -> 0 | C19: =+SUM('Breakdown '!E14:G14) -> 0 | D19: =+SUM('Breakdown '!H14:J14) -> 0 | E19: =+SUM('Breakdown '!K14:M14) -> 0 | F19: =+SUM('Breakdown '!L14:N14) -> 0 | G19: =+SUM('Breakdown '!M14:O14) -> 0 | H19: =+SUM('Breakdown '!N14:P14) -> 0 | I19: =SUM(B19:H19) -> 0 | J19: 0 | K19: 46308 | L19: =_xlfn.ISOWEEKNUM(K19) -> 42
A20: 2026/43 | B20: =+SUM('Breakdown '!B15:D15) -> 0 | C20: =+SUM('Breakdown '!E15:G15) -> 0 | D20: =+SUM('Breakdown '!H15:J15) -> 0 | E20: =+SUM('Breakdown '!K15:M15) -> 0 | F20: =+SUM('Breakdown '!L15:N15) -> 0 | G20: =+SUM('Breakdown '!M15:O15) -> 0 | H20: =+SUM('Breakdown '!N15:P15) -> 0 | I20: =SUM(B20:H20) -> 0 | J20: =I20+J19 -> 0 | K20: =K19+7 -> 46315 | L20: =_xlfn.ISOWEEKNUM(K20) -> 43
A21: 2026/44 | B21: =+SUM('Breakdown '!B16:D16) -> 0 | C21: =+SUM('Breakdown '!E16:G16) -> 0 | D21: =+SUM('Breakdown '!H16:J16) -> 0 | E21: =+SUM('Breakdown '!K16:M16) -> 0 | F21: =+SUM('Breakdown '!L16:N16) -> 0 | G21: =+SUM('Breakdown '!M16:O16) -> 0 | H21: =+SUM('Breakdown '!N16:P16) -> 0 | I21: =SUM(B21:H21) -> 0 | J21: =I21+J20 -> 0 | K21: =K20+7 -> 46322 | L21: =_xlfn.ISOWEEKNUM(K21) -> 44
A22: 2026/45 | B22: =+SUM('Breakdown '!B17:D17) -> 0 | C22: =+SUM('Breakdown '!E17:G17) -> 0 | D22: =+SUM('Breakdown '!H17:J17) -> 0 | E22: =+SUM('Breakdown '!K17:M17) -> 0 | F22: =+SUM('Breakdown '!L17:N17) -> 0 | G22: =+SUM('Breakdown '!M17:O17) -> 0 | H22: =+SUM('Breakdown '!N17:P17) -> 0 | I22: =SUM(B22:H22) -> 0 | J22: =I22+J21 -> 0 | K22: =K21+7 -> 46329 | L22: =_xlfn.ISOWEEKNUM(K22) -> 45
A23: 2026/46 | B23: =+SUM('Breakdown '!B18:D18) -> 0 | C23: =+SUM('Breakdown '!E18:G18) -> 0 | D23: =+SUM('Breakdown '!H18:J18) -> 0 | E23: =+SUM('Breakdown '!K18:M18) -> 0 | F23: =+SUM('Breakdown '!L18:N18) -> 0 | G23: =+SUM('Breakdown '!M18:O18) -> 0 | H23: =+SUM('Breakdown '!N18:P18) -> 0 | I23: =SUM(B23:H23) -> 0 | J23: =I23+J22 -> 0 | K23: =K22+7 -> 46336 | L23: =_xlfn.ISOWEEKNUM(K23) -> 46
A24: 2026/47 | B24: =+SUM('Breakdown '!B19:D19) -> 0 | C24: =+SUM('Breakdown '!E19:G19) -> 0 | D24: =+SUM('Breakdown '!H19:J19) -> 0 | E24: =+SUM('Breakdown '!K19:M19) -> 0 | F24: =+SUM('Breakdown '!L19:N19) -> 0 | G24: =+SUM('Breakdown '!M19:O19) -> 0 | H24: =+SUM('Breakdown '!N19:P19) -> 0 | I24: =SUM(B24:H24) -> 0 | J24: =I24+J23 -> 0 | K24: =K23+7 -> 46343 | L24: =_xlfn.ISOWEEKNUM(K24) -> 47
A25: 2026/48 | B25: =+SUM('Breakdown '!B20:D20) -> 0 | C25: =+SUM('Breakdown '!E20:G20) -> 140.4 | D25: =+SUM('Breakdown '!H20:J20) -> 0 | E25: =+SUM('Breakdown '!K20:M20) -> 0 | F25: =+SUM('Breakdown '!L20:N20) -> 0 | G25: =+SUM('Breakdown '!M20:O20) -> 0 | H25: =+SUM('Breakdown '!N20:P20) -> 0 | I25: =SUM(B25:H25) -> 140.4 | J25: =I25+J24 -> 140.4 | K25: =K24+7 -> 46350 | L25: =_xlfn.ISOWEEKNUM(K25) -> 48
A26: 2026/49 | B26: =+SUM('Breakdown '!B21:D21) -> 0 | C26: =+SUM('Breakdown '!E21:G21) -> 0 | D26: =+SUM('Breakdown '!H21:J21) -> 0 | E26: =+SUM('Breakdown '!K21:M21) -> 468 | F26: =+SUM('Breakdown '!L21:N21) -> 312 | G26: =+SUM('Breakdown '!M21:O21) -> 156 | H26: =+SUM('Breakdown '!N21:P21) -> 0 | I26: =SUM(B26:H26) -> 936 | J26: =I26+J25 -> 1076.4 | K26: =K25+7 -> 46357 | L26: =_xlfn.ISOWEEKNUM(K26) -> 49
A27: 2026/50 | B27: =+SUM('Breakdown '!B22:D22) -> 468 | C27: =+SUM('Breakdown '!E22:G22) -> 0 | D27: =+SUM('Breakdown '!H22:J22) -> 0 | E27: =+SUM('Breakdown '!K22:M22) -> 0 | F27: =+SUM('Breakdown '!L22:N22) -> 0 | G27: =+SUM('Breakdown '!M22:O22) -> 0 | H27: =+SUM('Breakdown '!N22:P22) -> 0 | I27: =SUM(B27:H27) -> 468 | J27: =I27+J26 -> 1544.4 | K27: =K26+7 -> 46364 | L27: =_xlfn.ISOWEEKNUM(K27) -> 50
A28: 2026/51 | B28: =+SUM('Breakdown '!B23:D23) -> 0 | C28: =+SUM('Breakdown '!E23:G23) -> 468 | D28: =+SUM('Breakdown '!H23:J23) -> 0 | E28: =+SUM('Breakdown '!K23:M23) -> 0 | F28: =+SUM('Breakdown '!L23:N23) -> 0 | G28: =+SUM('Breakdown '!M23:O23) -> 0 | H28: =+SUM('Breakdown '!N23:P23) -> 0 | I28: =SUM(B28:H28) -> 468 | J28: =I28+J27 -> 2012.4 | K28: =K27+7 -> 46371 | L28: =_xlfn.ISOWEEKNUM(K28) -> 51
A29: 2026/52 | B29: =+SUM('Breakdown '!B24:D24) -> 0 | C29: =+SUM('Breakdown '!E24:G24) -> 0 | D29: =+SUM('Breakdown '!H24:J24) -> 0 | E29: =+SUM('Breakdown '!K24:M24) -> 748.8 | F29: =+SUM('Breakdown '!L24:N24) -> 499.2 | G29: =+SUM('Breakdown '!M24:O24) -> 249.6 | H29: =+SUM('Breakdown '!N24:P24) -> 0 | I29: =SUM(B29:H29) -> 1497.6 | J29: =I29+J28 -> 3510 | K29: =K28+7 -> 46378 | L29: =_xlfn.ISOWEEKNUM(K29) -> 52
A30: 2026/53 | B30: =+SUM('Breakdown '!B25:D25) -> 374.4 | C30: =+SUM('Breakdown '!E25:G25) -> 0 | D30: =+SUM('Breakdown '!H25:J25) -> 0 | E30: =+SUM('Breakdown '!K25:M25) -> 0 | F30: =+SUM('Breakdown '!L25:N25) -> 0 | G30: =+SUM('Breakdown '!M25:O25) -> 0 | H30: =+SUM('Breakdown '!N25:P25) -> 0 | I30: =SUM(B30:H30) -> 374.4 | J30: =I30+J29 -> 3884.4 | K30: =K29+7 -> 46385 | L30: =_xlfn.ISOWEEKNUM(K30) -> 53
A31: 2027/01 | B31: =+SUM('Breakdown '!B26:D26) -> 468 | C31: =+SUM('Breakdown '!E26:G26) -> 702 | D31: =+SUM('Breakdown '!H26:J26) -> 0 | E31: =+SUM('Breakdown '!K26:M26) -> 0 | F31: =+SUM('Breakdown '!L26:N26) -> 0 | G31: =+SUM('Breakdown '!M26:O26) -> 0 | H31: =+SUM('Breakdown '!N26:P26) -> 0 | I31: =SUM(B31:H31) -> 1170 | J31: =I31+J30 -> 5054.4 | K31: =K30+7 -> 46392 | L31: =_xlfn.ISOWEEKNUM(K31) -> 1
... A51: 2027/21 | B51: =+SUM('Breakdown '!B46:D46) -> 0 | C51: =+SUM('Breakdown '!E46:G46) -> 0 | D51: =+SUM('Breakdown '!H46:J46) -> 0 | E51: =+SUM('Breakdown '!K46:M46) -> 0 | F51: =+SUM('Breakdown '!L46:N46) -> 156 | G51: =+SUM('Breakdown '!M46:O46) -> 312 | H51: =+SUM('Breakdown '!N46:P46) -> 468 | I51: =SUM(B51:H51) -> 936 | J51: =I51+J50 -> 23915.4 | K51: =K50+7 -> 46532 | L51: =_xlfn.ISOWEEKNUM(K51) -> 21
A52: 2027/22 | B52: =+SUM('Breakdown '!B47:D47) -> 0 | C52: =+SUM('Breakdown '!E47:G47) -> 0 | D52: =+SUM('Breakdown '!H47:J47) -> 0 | E52: =+SUM('Breakdown '!K47:M47) -> 421.2 | F52: =+SUM('Breakdown '!L47:N47) -> 280.8 | G52: =+SUM('Breakdown '!M47:O47) -> 140.4 | H52: =+SUM('Breakdown '!N47:P47) -> 0 | I52: =SUM(B52:H52) -> 842.4 | J52: =I52+J51 -> 24757.8 | K52: 45831 | L52: =_xlfn.ISOWEEKNUM(K52) -> 26
A53: 2027/23 | B53: =+SUM('Breakdown '!B48:D48) -> 561.6 | C53: =+SUM('Breakdown '!E48:G48) -> 0 | D53: =+SUM('Breakdown '!H48:J48) -> 0 | E53: =+SUM('Breakdown '!K48:M48) -> 0 | F53: =+SUM('Breakdown '!L48:N48) -> 0 | G53: =+SUM('Breakdown '!M48:O48) -> 0 | H53: =+SUM('Breakdown '!N48:P48) -> 0 | I53: =SUM(B53:H53) -> 561.6 | J53: =I53+J52 -> 25319.4 | K53: =K51+7 -> 46539 | L53: =_xlfn.ISOWEEKNUM(K53) -> 22
A54: 2027/24 | B54: =+SUM('Breakdown '!B49:D49) -> 187.2 | C54: =+SUM('Breakdown '!E49:G49) -> 93.6 | D54: =+SUM('Breakdown '!H49:J49) -> 0 | E54: =+SUM('Breakdown '!K49:M49) -> 46.8 | F54: =+SUM('Breakdown '!L49:N49) -> 31.2 | G54: =+SUM('Breakdown '!M49:O49) -> 15.6 | H54: =+SUM('Breakdown '!N49:P49) -> 0 | I54: =SUM(B54:H54) -> 374.4 | J54: =I54+J53 -> 25693.8 | K54: =K53+7 -> 46546 | L54: =_xlfn.ISOWEEKNUM(K54) -> 23
A55: 2027/25 | B55: =+SUM('Breakdown '!B50:D50) -> 0 | C55: =+SUM('Breakdown '!E50:G50) -> 0 | D55: =+SUM('Breakdown '!H50:J50) -> 0 | E55: =+SUM('Breakdown '!K50:M50) -> 140.4 | F55: =+SUM('Breakdown '!L50:N50) -> 249.6 | G55: =+SUM('Breakdown '!M50:O50) -> 358.8 | H55: =+SUM('Breakdown '!N50:P50) -> 468 | I55: =SUM(B55:H55) -> 1216.8 | J55: =I55+J54 -> 26910.6 | K55: =K54+7 -> 46553 | L55: =_xlfn.ISOWEEKNUM(K55) -> 24
A56: 2027/26 | B56: =+SUM('Breakdown '!B51:D51) -> 0 | C56: =+SUM('Breakdown '!E51:G51) -> 327.6 | D56: =+SUM('Breakdown '!H51:J51) -> 0 | E56: =+SUM('Breakdown '!K51:M51) -> 0 | F56: =+SUM('Breakdown '!L51:N51) -> 0 | G56: =+SUM('Breakdown '!M51:O51) -> 0 | H56: =+SUM('Breakdown '!N51:P51) -> 0 | I56: =SUM(B56:H56) -> 327.6 | J56: =I56+J55 -> 27238.2 | K56: =K55+7 -> 46560 | L56: =_xlfn.ISOWEEKNUM(K56) -> 25
A57: 2027/27 | B57: =+SUM('Breakdown '!B52:D52) -> 0 | C57: =+SUM('Breakdown '!E52:G52) -> 0 | D57: =+SUM('Breakdown '!H52:J52) -> 0 | E57: =+SUM('Breakdown '!K52:M52) -> 374.4 | F57: =+SUM('Breakdown '!L52:N52) -> 249.6 | G57: =+SUM('Breakdown '!M52:O52) -> 124.8 | H57: =+SUM('Breakdown '!N52:P52) -> 0 | I57: =SUM(B57:H57) -> 748.8 | J57: =I57+J56 -> 27987 | K57: =K56+7 -> 46567 | L57: =_xlfn.ISOWEEKNUM(K57) -> 26
A58: 2027/28 | B58: =+SUM('Breakdown '!B53:D53) -> 0 | C58: =+SUM('Breakdown '!E53:G53) -> 0 | D58: =+SUM('Breakdown '!H53:J53) -> 0 | E58: =+SUM('Breakdown '!K53:M53) -> 0 | F58: =+SUM('Breakdown '!L53:N53) -> 171.6 | G58: =+SUM('Breakdown '!M53:O53) -> 343.2 | H58: =+SUM('Breakdown '!N53:P53) -> 514.8 | I58: =SUM(B58:H58) -> 1029.6 | J58: =I58+J57 -> 29016.6 | K58: =K57+7 -> 46574 | L58: =_xlfn.ISOWEEKNUM(K58) -> 27
A59: 2027/29 | B59: =+SUM('Breakdown '!B54:D54) -> 577.2 | C59: =+SUM('Breakdown '!E54:G54) -> 0 | D59: =+SUM('Breakdown '!H54:J54) -> 0 | E59: =+SUM('Breakdown '!K54:M54) -> 0 | F59: =+SUM('Breakdown '!L54:N54) -> 0 | G59: =+SUM('Breakdown '!M54:O54) -> 0 | H59: =+SUM('Breakdown '!N54:P54) -> 0 | I59: =SUM(B59:H59) -> 577.2 | J59: =I59+J58 -> 29593.8 | K59: =K58+7 -> 46581 | L59: =_xlfn.ISOWEEKNUM(K59) -> 28
A60: 2027/30 | B60: =+SUM('Breakdown '!B55:D55) -> 0 | C60: =+SUM('Breakdown '!E55:G55) -> 0 | D60: =+SUM('Breakdown '!H55:J55) -> 0 | E60: =+SUM('Breakdown '!K55:M55) -> 140.4 | F60: =+SUM('Breakdown '!L55:N55) -> 280.8 | G60: =+SUM('Breakdown '!M55:O55) -> 421.2 | H60: =+SUM('Breakdown '!N55:P55) -> 561.6 | I60: =SUM(B60:H60) -> 1404 | J60: =I60+J59 -> 30997.8 | K60: =K59+7 -> 46588 | L60: =_xlfn.ISOWEEKNUM(K60) -> 29
A61: 2027/31 | B61: =+SUM('Breakdown '!B56:D56) -> 0 | C61: =+SUM('Breakdown '!E56:G56) -> 0 | D61: =+SUM('Breakdown '!H56:J56) -> 0 | E61: =+SUM('Breakdown '!K56:M56) -> 187.2 | F61: =+SUM('Breakdown '!L56:N56) -> 124.8 | G61: =+SUM('Breakdown '!M56:O56) -> 62.4 | H61: =+SUM('Breakdown '!N56:P56) -> 0 | I61: =SUM(B61:H61) -> 374.4 | J61: =I61+J60 -> 31372.2 | K61: =K60+7 -> 46595 | L61: =_xlfn.ISOWEEKNUM(K61) -> 30
A62: 2027/32 | B62: =+SUM('Breakdown '!B57:D57) -> 218.4 | C62: =+SUM('Breakdown '!E57:G57) -> 0 | D62: =+SUM('Breakdown '!H57:J57) -> 0 | E62: =+SUM('Breakdown '!K57:M57) -> 842.4 | F62: =+SUM('Breakdown '!L57:N57) -> 561.6 | G62: =+SUM('Breakdown '!M57:O57) -> 280.8 | H62: =+SUM('Breakdown '!N57:P57) -> 0 | I62: =SUM(B62:H62) -> 1903.2 | J62: =I62+J61 -> 33275.4 | K62: =K61+7 -> 46602 | L62: =_xlfn.ISOWEEKNUM(K62) -> 31
A63: 2027/33 | B63: =+SUM('Breakdown '!B58:D58) -> 0 | C63: =+SUM('Breakdown '!E57:G57) -> 0 | D63: =+SUM('Breakdown '!H58:J58) -> 0 | E63: =+SUM('Breakdown '!K58:M58) -> 468 | F63: =+SUM('Breakdown '!L58:N58) -> 592.8 | G63: =+SUM('Breakdown '!M58:O58) -> 717.6 | H63: =+SUM('Breakdown '!N58:P58) -> 842.4 | I63: =SUM(B63:H63) -> 2620.8 | J63: =I63+J62 -> 35896.2 | K63: =K62+7 -> 46609 | L63: =_xlfn.ISOWEEKNUM(K63) -> 32
...

Sheet Release Qty
A3: 45933
A16: 45950
A21: 46293
A76: 46079
